Workbook
Name __xlnm_Print_Area_1: #REF!

Sheet Organograma
E4: Organograma
E5: 4 de setembro de 2026

Sheet Premissas
C4: Premissas e Fatos da Operação
C5: 4 de setembro de 2026
B6: Fatos da operação (Acordo de Investimento, Ofício BACEN 31070/2026, calls Deloitte/SF e material SF de 31.08.2026)
B8: • Incorporação: a Embracon incorpora a CNP (incorporação plena, aprovada pelo BACEN); o acervo da CNP entra pelo valor de mercado apurado em laudo (PPA) e as Partes CNP recebem 13,8% do capital da Embracon (relação de troca).
B9: • Cash-out simultâneo: as Partes CNP adquirem das Holdings 26,2% da Embracon (13,1% de cada uma) por R$ 1.200 milhões, desconsiderando correção pelo IPCA, ajustes de caixa e eventual earn-out de até R$ 680 milhões. A secundária é entendida como concomitante à incorporação (operação única).
B10: • Posição final: famílias 60% (Savian 30% e JVFJ 30%) e Grupo CNP 40%.
B11: • Qualificação contábil em discussão: combinação de negócios (CPC 15 — leitura do contrato e da Stocche Forbes; o PL da Embracon não é reavaliado) ou operação em conjunto (CPC 19 — leitura da Deloitte a partir dos vetos qualificados da CNP; Embracon e CNP reavaliadas a valor justo, com passivo fiscal diferido).
B12: • Objetivo do material: ilustrar, para Savian e JVFJ, os impactos de cada qualificação sobre o custo do investimento, o imposto no cash-out e o imposto na venda futura dos 60% (pela Holding ou pelas pessoas físicas).
B14: Premissas numéricas — inputs do modelo (células cinza; alterações aqui propagam para todas as abas)
B16: Premissa | C16: Valor | D16: Origem / observação
B17: Data-base dos balanços | C17: 30.06.2026 | D17: Balanços esboçados pela Embracon (agosto/2026), não definitivos
B18: Unidade monetária | C18: R$ milhões
B19: PL contábil da Embracon (antes da incorporação) | C19: 254 | D19: Corresponde ao custo original do investimento das Holdings (Savian + JVFJ)
B20: Investimento original — Savian (50% do PL da Embracon) | C20: =C19/2 -> 127 | D20: Derivado: as Holdings são simétricas no modelo (50/50); a aba 'Cálculos da Operação' dobra a coluna Savian para obter os totais
B21: Investimento original — JVFJ (50% do PL da Embracon) | C21: =C20 -> 127 | D21: Derivado: igual ao custo da Savian (simetria das Holdings)
B22: PL contábil da CNP | C22: 800 | D22: Esboço da Embracon; o material SF de 31.08 usava 839
B23: Valor de mercado da CNP (valor incorporado no CPC 15 — PPA) | C23: 822 | D23: ≈ EV da CNP no Acordo de Investimento (R$ 821,9 mi, data-base 31.12.2024); a diferença para o PL contábil é a mais-valia
B24: Valor justo da Embracon (EV — Acordo de Investimento, data-base 31.12.2024) | C24: 5133 | D24: Usado apenas no cenário CPC 19 (reavaliação da Embracon); o material SF de 31.08 usava o EV total DTT de 5.588
B25: Participação das Partes CNP na incorporação (relação de troca) | C25: 0.138 | D25: Ações novas emitidas pela Embracon às Partes CNP
B26: Participação-alvo final das Partes CNP | C26: 0.4 | D26: Após o cash-out
B27: Preço do cash-out (compra de 26,2% das Holdings) | C27: 1200 | D27: Sem IPCA, ajustes de caixa e earn-out (até 680)
B28: IRPJ/CSLL — ganho de capital das Holdings | C28: 0.34 | D28: Alíquota combinada
B29: IR — ganho de capital das pessoas físicas (simplificada) | C29: 0.225 | D29: Adotada a alíquota máxima da tabela progressiva, por simplificação
B30: Custo das quotas das Holdings nas pessoas físicas | C30: 18 | D30: Premissa ilustrativa (exercício MLA), a confirmar com o custo real das quotas
B31: Preço de venda futura — abaixo do valor justo | C31: 1000 | D31: Cenário (i) do material SF
B32: Preço de venda futura — igual ao valor justo (60% do valor justo da JO) | C32: ='CPC 19'!D22 -> 3573 | D32: Cenário (ii): calculado na aba CPC 19 (quadro 2, valor justo total × 60%)
B33: Preço de venda futura — acima do valor justo | C33: 5000 | D33: Cenário (iii) do material SF
B35: Valores derivados das premissas
B36: Participação final das famílias (Savian + JVFJ) | C36: =1-C26 -> 0.6
B37: Mais-valia da CNP (valor de mercado − PL contábil) | C37: =C23-C22 -> 22
B38: Percentual vendido no cash-out (alvo CNP − relação de troca) | C38: =C26-C25 -> 0.262
B39: Fração do investimento de cada Holding alienada no cash-out (13,1% ÷ 43,1%) | C39: ='Cálculos da Operação'!D71 -> 0.30394432 | D39: Critério de alocação de custo da aba 'Cálculos da Operação'; o material SF de 31.08 alocava 26,2% do custo (13,1% por Holding)
B41: Premissas fiscais e ressalvas (material SF de 31.08.2026 e critérios adotados neste modelo)
B43: • Custo alocado no cash-out (critério deste modelo, herdado da aba 'Cálculos da Operação'; o material SF de 31.08 alocava 26,2% do custo, 13,1% de cada Holding): a secundária é tratada como concomitante à incorporação e o custo de cada Holding é alocado proporcionalmente à fração alienada (13,1% ÷ 43,1%). O imposto do cash-out é apurado na aba 'Cálculos da Operação' nos cenários A (custo original) e B (custo incrementado).
B44: • Regime das Holdings: lucro presumido — premissa relevante para a tributação do cash-out. Na futura alienação dos 60% remanescentes, a carga poderá ser reduzida se, à época, as Holdings estiverem no lucro real e dispuserem de prejuízos fiscais e bases negativas de CSLL compensáveis, observadas as limitações aplicáveis.
B45: • Segregação de risco no CPC 15: o custo das Holdings é aberto em custo original (incontroverso), reflexo do PL contábil da CNP (neutralidade do MEP — art. 33, §2º, do DL 1.598/77; precedente WTorre, com decisões CARF de 2024 em sentido contrário — fundamentos discutidos nas calls com a SF) e reflexo da mais-valia (parcela mais exposta). No material de 31.08 a mais-valia era estimada em 34,6% do PL da CNP (proporção DTT 300/866); aqui é o valor de mercado menos o PL contábil.
B46: • CPC 19: o ganho de avaliação a valor justo (AVJ) tem tributação diferida, controlado em subconta (arts. 13 e 14 da Lei 12.973/14), fica 'carimbado' a 34% e é devido na realização do investimento, independentemente da entidade que aliene a participação.
B47: • ITCMD: não analisado neste material. Em caráter preliminar, o cenário de operação em conjunto pode elevar o valor patrimonial das Holdings (reconhecimento a valor justo da CNP e da Embracon), com possível repercussão na base do imposto, a depender do critério legal aplicável.
B48: • Caráter ilustrativo: os exemplos foram elaborados com informações estimadas, de diversas fontes, não auditadas; não substituem a análise dos documentos definitivos da Transação e da contabilização efetivamente adotada, nem devem ser entendidos como estimativa de custo ou contingência tributária.

Sheet Cálculos da Operação
E4: Cálculo da Operação e Ganho de Capital
E5: 4 de setembro de 2026
B10: Premissas econômicas
B12: Patrimonio Liquido | E12: Informações Adicionais
B13: SAVIAN | C13: =Premissas!C20 -> 127 | E13: Data-base dos balanços | I13: =Premissas!C17 -> 30.06.2026
B14: Invest. Embracon | C14: =Premissas!C20 -> 127 | E14: Unidade | I14: =Premissas!C18 -> R$ milhões
E15: Participação das Partes CNP na incorporação (relação de troca) | I15: =Premissas!C25 -> 0.138
B16: JVFJ | C16: =Premissas!C21 -> 127 | E16: Participação-alvo final das Partes na CNPH | I16: =Premissas!C26 -> 0.4
B17: Invest. Embracon | C17: =Premissas!C21 -> 127 | E17: IRPJ/CSLL — ganho de capital PJ | I17: =Premissas!C28 -> 0.34
B19: EMBRACON | C19: =Premissas!C19 -> 254
B20: SAVIAN | C20: =C16/C19 -> 0.5
B21: JVFJ | C21: =C16/C19 -> 0.5
B23: CNP | C23: =Premissas!C22 -> 800
B24: Valor de Mercado CNP | C24: =Premissas!C23 -> 822
B26: CPC 15 — Combinação de Negócios
B28: 1) Incorporação CNPH
B30: Participação Societária (Embracon)
C31: Antes | D31: Após Inc
B32: SAVIAN | C32: 0.5 | D32: =C32*(1-I15) -> 0.431
B33: JVFJ | C33: 0.5 | D33: =C33*(1-I15) -> 0.431
B34: CNPH (ações novas) | C34: - | D34: =I15 -> 0.138
D35: =SUM(D32:D34) -> 1
B37: Embracon - Incorporação do Acervo
B38: EMBRACON | C38: =C19 -> 254 | D38: =C38/C$40 -> 0.23605948
B39: CNP | C39: =C24 -> 822 | D39: =C39/C$40 -> 0.76394052
B40: (=) Total | C40: =C38+C39 -> 1076 | D40: =D38+D39 -> 1
B42: PL Embracon (pós inc) | C42: =C43+C44+C45 -> 1076
B43: SAVIAN | C43: =D32*C40 -> 463.756
B44: JVFJ | C44: =D33*C40 -> 463.756
B45: CNP | C45: =D34*C40 -> 148.488
B47: Reflexo nas Holdings (MEP) - Custo de Investimento | H47: Lançamentos Contábeis (Holdings)
D48: SAVIAN | E48: JVFJ | F48: Total | I48: Débitos | J48: Crédito
B49: Custo Original (Investimento anterior) | D49: =C14 -> 127 | E49: =C14 -> 127 | F49: =D49+E49 -> 254 | H49: Reflexo da Incorporação | I49: =D50 -> 411
B50: (+) Incorporação base | D50: =C39/2 -> 411 | E50: =C39/2 -> 411 | F50: =D50+E50 -> 822 | H50: Perda de diluição | J50: =D51 -> -74.244
B51: (-) Diluição (13,8%) | D51: =-(D49+D50)*I15 -> -74.244 | E51: =-(E49+E50)*I15 -> -74.244 | F51: =D51+E51 -> -148.488 | H51: (=) Efeito Líquido do Investimento | J51: =I49+J50 -> 336.756
B52: (=) Parcela liquida incorporada | D52: =D50+D51 -> 336.756 | E52: =E50+E51 -> 336.756 | F52: =D52+E52 -> 673.512
B54: Custo do Investimento Incrementado (Alternativa)
B55: (=) Custo Incrementado | D55: 2 x 463,75 -> | E55: =2*(D56+D57) -> 927.512
B56: Custo Original | D56: =C14 -> 127 | E56: =C17 -> 127
B57: Acervo liquido incorporado | D57: =D52 -> 336.756 | E57: =E52 -> 336.756
...

Sheet CPC 19
C4: CPC 19 — Joint Operation
C5: 4 de setembro de 2026
B6: CPC 19 — Joint Operation: reconhecimento de 60% do valor justo da JO e imposto diferido 'carimbado'
B8: Na operação em conjunto (CPC 19), leitura sustentada pela Deloitte a partir dos vetos qualificados da CNP, as Holdings deixam de avaliar o investimento pelo método de equivalência patrimonial e passam a reconhecer diretamente a sua parcela (60%) dos ativos e passivos da JO — Embracon e CNP — a valor justo. Isso inclui o valor justo da própria Embracon, que no CPC 15 não é reavaliada. O ganho de avaliação a valor justo (AVJ) não é tributado no reconhecimento, desde que controlado em subconta (arts. 13 e 14 da Lei 12.973/14), mas fica 'carimbado': o IRPJ/CSLL de 34% sobre o AVJ é devido quando o investimento for realizado (venda), qualquer que seja o preço e independentemente de quem venda. As premissas (valor justo da Embracon pelo EV do Acordo de Investimento e valor de mercado da CNP) vêm da aba 'Premissas'.
B10: 1) Avaliação a valor justo da JO (100%)
B11: Componente | C11: Valor | D11: Origem / leitura
B12: Valor justo da Embracon (EV — Acordo de Investimento) | C12: =Premissas!C24 -> 5133 | D12: Aba Premissas. No CPC 15 a Embracon não é reavaliada; no CPC 19 entra integralmente a valor justo.
B13: Valor justo da CNP (= valor de mercado incorporado) | C13: =Premissas!C23 -> 822 | D13: Aba Premissas; mesmo valor incorporado no CPC 15.
B14: (=) Valor justo total da JO | C14: =C12+C13 -> 5955 | D14: Embracon + CNP a valor justo.
B15: (−) Base contábil (PL da Embracon + PL contábil da CNP) | C15: =Premissas!C19+Premissas!C22 -> 1054 | D15: Patrimônio a valor contábil das duas companhias.
B16: (=) Ganho de AVJ total da JO | C16: =C14-C15 -> 4901 | D16: Diferença entre valor justo e base contábil; tributação diferida (subconta).
B18: 2) Investimento das Holdings na JO (60% — após o cash-out)
B19: Componente | C19: 100% da JO | D19: 60% (Holdings) | E19: Leitura
B20: Valor justo da Embracon | C20: =C12 -> 5133 | D20: =C20*Premissas!C36 -> 3079.8 | E20: Parcela que não existe no CPC 15: a Embracon passa a ser reavaliada.
B21: Valor justo da CNP | C21: =C13 -> 822 | D21: =C21*Premissas!C36 -> 493.2 | E21: Mesmo valor incorporado no CPC 15.
B22: (=) Valor justo total — custo do investimento das Holdings no CPC 19 | C22: =C20+C21 -> 5955 | D22: =D20+D21 -> 3573 | E22: Investimento reconhecido pelas Holdings: 60% do valor justo de Embracon + CNP.
B23: (−) Base contábil (PL da Embracon + PL contábil da CNP) | C23: =C15 -> 1054 | D23: =C23*Premissas!C36 -> 632.4 | E23: Coincide com o custo do CPC 15 sem a camada da mais-valia (custo original + reflexo do PL contábil da CNP).
B24: (=) Ganho de AVJ com tributação diferida (subconta — arts. 13 e 14, Lei 12.973/14) | C24: =C22-C23 -> 4901 | D24: =D22-D23 -> 2940.6 | E24: Ganho reconhecido no resultado das Holdings e neutralizado fiscalmente apenas enquanto controlado em subconta.
B25: Passivo fiscal diferido 'carimbado' (34% × AVJ) | C25: =C24*Premissas!C28 -> 1666.34 | D25: =D24*Premissas!C28 -> 999.804 | E25: Devido na realização do investimento (venda), independentemente do preço; é o piso de imposto do CPC 19 na venda futura.
B26: Custo do investimento das Holdings — CPC 19 (60% do valor justo) | C26: =C22 -> 5955 | D26: =D22 -> 3573 | E26: Valor levado às abas 'Alienação Futura' e 'Conclusão'.
B28: 3) Lançamentos contábeis nas Holdings — CPC 19 (60%)
B29: Lançamento | C29: Débito | D29: Crédito | E29: Comentário
B30: Investimento na JO (60% do valor justo de Embracon + CNP) | C30: =D22 -> 3573 | D30: – | E30: Reconhecimento direto da parcela das Holdings nos ativos e passivos da JO.
B31: Investimento em Embracon avaliado pelo MEP (base contábil, 60%) | C31: – | D31: =D23 -> 632.4 | E31: Baixa do investimento a valor contábil (custo original + reflexo do PL contábil da CNP).
B32: Ganho de avaliação a valor justo — resultado (controlado em subconta) | C32: – | D32: =D24 -> 2940.6 | E32: Neutralizado fiscalmente enquanto em subconta (arts. 13 e 14 da Lei 12.973/14).
B33: Despesa de IRPJ/CSLL diferidos — resultado | C33: =D25 -> 999.804 | D33: – | E33: Reconhecimento do imposto sobre o AVJ.
B34: Passivo fiscal diferido (34% × AVJ, 'carimbado') | C34: – | D34: =D25 -> 999.804 | E34: Realizado (pago) na venda do investimento, qualquer que seja o preço.
B35: (=) Totais (débitos = créditos) | C35: =SUM(C30:C34) -> 4572.804 | D35: =SUM(D30:D34) -> 4572.804 | E35: =ROUND(C35-D35,6) -> 0 | F35: ← conferência ('ok' = partidas dobradas fechadas)
B37: 4) Custo do investimento das Holdings após o cash-out — CPC 15 × CPC 19
B38: Cenário | C38: Custo (60%) | D38: Δ vs. CPC 15 | E38: Leitura
B39: CPC 15 — custo incrementado remanescente (aba 'Cálculos da Operação', cenário B) | C39: ='Cálculos da Operação'!J93 -> 645.6 | D39: – | E39: Custo original + reflexo da CNP a valor de mercado, líquido da parcela baixada no cash-out; sem passivo fiscal diferido.
B40: CPC 19 — 60% do valor justo da JO (quadro 2) | C40: =D22 -> 3573 | D40: =C40-C39 -> 2927.4 | E40: A diferença é o AVJ de toda a JO (60%) menos a mais-valia da CNP que o CPC 15 já leva ao custo; sobre o AVJ há IR diferido de 34%.
B41: Parcela do custo CPC 19 com IR diferido (AVJ, 60%) e imposto 'carimbado' | C41: =D24 -> 2940.6 | D41: =D25 -> 999.804 | E41: Coluna Δ = imposto carimbado (34% × AVJ), devido na venda em qualquer cenário de preço.
B43: Leitura: no CPC 19 o custo das Holdings sobe para 60% do valor justo de toda a JO, mas o acréscimo é integralmente 'carimbado' — o IR diferido de 34% sobre o AVJ é devido na venda, qualquer que seja o preço, e permanece na Holding mesmo que a venda seja feita pelas pessoas físicas. Elimina-se a discussão sobre o custo, ao preço de reconhecer ganho sobre a própria Embracon (não reavaliada no CPC 15) e de elevar o valor patrimonial das Holdings, com possível impacto na base do ITCMD. A comparação com o CPC 15 na venda futura está na aba 'Alienação Futura (PJ x PF)'.

Sheet Alienação Futura (PJ x PF)
C4: Alienação Futura — Análise dos Cenários
C5: 4 de setembro de 2026
B6: 1) Premissas utilizadas na simulação da venda futura dos 60%
B8: Informação | C8: Valor | D8: Origem
B9: Participação final das famílias (Savian + JVFJ) | C9: =Premissas!C36 -> 0.6 | D9: Aba Premissas
B10: IRPJ/CSLL — ganho de capital das Holdings | C10: =Premissas!C28 -> 0.34 | D10: Aba Premissas
B11: IR — ganho de capital das pessoas físicas (simplificada) | C11: =Premissas!C29 -> 0.225 | D11: Aba Premissas
B12: Custo das quotas das Holdings nas pessoas físicas | C12: =Premissas!C30 -> 18 | D12: Aba Premissas — premissa ilustrativa, a confirmar
B13: Custo fiscal do investimento — CPC 15 (custo incrementado remanescente após o cash-out) | C13: ='Cálculos da Operação'!J93 -> 645.6 | D13: Aba 'Cálculos da Operação', cenário B (custo remanescente)
B14: Custo fiscal original remanescente — CPC 15 (cenário A) | C14: ='Cálculos da Operação'!I93 -> 176.79814 | D14: Aba 'Cálculos da Operação', cenário A — usado na análise hipotética (RISCO 1)
B15: Mais-valia da CNP contida no custo CPC 15 (60%) | C15: =Premissas!C37*Premissas!C36 -> 13.2 | D15: Aba Premissas (valor de mercado − PL contábil) × 60% — usada na análise hipotética (RISCO 2)
B16: Base contábil — CPC 19 (60%) | C16: ='CPC 19'!D23 -> 632.4 | D16: Aba CPC 19
B17: Ganho de AVJ com tributação diferida — CPC 19 (60%) | C17: ='CPC 19'!D24 -> 2940.6 | D17: Aba CPC 19
B18: IR diferido 'carimbado' — CPC 19 (34% × AVJ) | C18: ='CPC 19'!D25 -> 999.804 | D18: Aba CPC 19
B19: Custo do investimento — CPC 19 (60% do valor justo da JO) | C19: ='CPC 19'!D26 -> 3573 | D19: Aba CPC 19
B20: Preço de venda — abaixo do valor justo | C20: =Premissas!C31 -> 1000 | D20: Aba Premissas
B21: Preço de venda — igual ao valor justo (60% do valor justo da JO) | C21: =Premissas!C32 -> 3573 | D21: Aba Premissas (= aba CPC 19)
B22: Preço de venda — acima do valor justo | C22: =Premissas!C33 -> 5000 | D22: Aba Premissas
B24: 2) Venda futura dos 60% — PJ x PF
B26: Simulamos a venda dos 60% remanescentes em três preços — abaixo, igual e acima do valor justo (60% do valor justo da JO). No CPC 15, o imposto incide sobre a diferença entre o preço e o custo fiscal incrementado remanescente (aba 'Cálculos da Operação'). No CPC 19, o imposto diferido de 34% sobre o AVJ é devido de qualquer forma e funciona como piso; se o preço superar o valor justo, o excedente também é tributado. Na venda pelas pessoas físicas (após 'subir' as ações das Holdings para as PFs), aplica-se a alíquota simplificada de 22,5% sobre o ganho; porém o custo das PFs é o custo das quotas das Holdings, muito inferior ao custo da Holding, e no CPC 19 o imposto carimbado permanece na Holding mesmo que a venda seja feita pela PF.
B28: Imposto na venda dos 60% | D28: CPC 15 | F28: CPC 19 | H28: Δ (CPC 19 − CPC 15)
B29: Cenário de preço | C29: Preço de venda | D29: Venda PJ | E29: Venda PF | F29: Venda PJ | G29: Venda PF | H29: Venda PJ | I29: Venda PF
B30: Abaixo do valor justo | C30: =$C$20 -> 1000 | D30: =(C30-$C$13)*$C$10 -> 120.496 | E30: =(C30-$C$12)*$C$11 -> 220.95 | F30: =MAX($C$18,(C30-$C$16)*$C$10) -> 999.804 | G30: =$C$18+MAX(0,C30-$C$19)*$C$11 -> 999.804 | H30: =F30-D30 -> 879.308 | I30: =G30-E30 -> 778.854
B31: Igual ao valor justo | C31: =$C$21 -> 3573 | D31: =(C31-$C$13)*$C$10 -> 995.316 | E31: =(C31-$C$12)*$C$11 -> 799.875 | F31: =MAX($C$18,(C31-$C$16)*$C$10) -> 999.804 | G31: =$C$18+MAX(0,C31-$C$19)*$C$11 -> 999.804 | H31: =F31-D31 -> 4.488 | I31: =G31-E31 -> 199.929
B32: Acima do valor justo | C32: =$C$22 -> 5000 | D32: =(C32-$C$13)*$C$10 -> 1480.496 | E32: =(C32-$C$12)*$C$11 -> 1120.95 | F32: =MAX($C$18,(C32-$C$16)*$C$10) -> 1484.984 | G32: =$C$18+MAX(0,C32-$C$19)*$C$11 -> 1320.879 | H32: =F32-D32 -> 4.488 | I32: =G32-E32 -> 199.929
B33: Fórmulas: CPC 15 PJ = (preço − custo incrementado remanescente) × 34% · CPC 15 PF = (preço − custo das quotas) × 22,5% · CPC 19 PJ = maior entre o imposto carimbado e (preço − base contábil) × 34% · CPC 19 PF = imposto carimbado na Holding + 22,5% sobre o excedente ao valor justo.
B34: Leitura: em preços iguais ou superiores ao valor justo, a diferença entre os regimes na venda pela Holding é pequena e corresponde a 34% da mais-valia da CNP — a única camada que o CPC 15 leva ao custo e o CPC 19 tributa. Abaixo do valor justo, o CPC 19 é substancialmente mais oneroso, porque o imposto diferido não diminui com o preço. A venda pela PF só é vantajosa no CPC 15, e apenas a partir de preços em que a alíquota menor compensa o custo menor das quotas; no CPC 19 ela não elimina o imposto carimbado, que permanece na Holding.
B36: Cenário alternativo — venda abaixo do valor justo e utilização da perda (CPC 19)
B37: Movimento na Holding (CPC 19) | C37: Valor | D37: Comentário
B38: Baixa do investimento (60% do valor justo da JO) | C38: =-$C$19 -> -3573 | D38: Valor contábil do investimento reconhecido no CPC 19.
B39: Preço recebido | C39: =$C$20 -> 1000
B40: (=) Resultado contábil da venda | C40: =C38+C39 -> -2573 | D40: Prejuízo contábil, porque o preço é inferior ao valor justo reconhecido.
B41: IR diferido 'carimbado' devido na realização | C41: =$C$18 -> 999.804 | D41: Devido integralmente: a subconta é baixada com a venda.
B42: Crédito teórico sobre a perda (34%) | C42: =C40*$C$10 -> -874.82 | D42: No lucro presumido a perda não é aproveitável; no lucro real, a compensação é limitada à trava de 30% e depende de lucros futuros.
B43: Imposto devido (se a perda fosse integralmente aproveitada) | C43: =C41+C42 -> 124.984 | D43: Coincide com o RISCO 2 da análise hipotética (mesma base contábil); nos quadros adota-se o piso = imposto carimbado.
B45: Análise hipotética — risco CPC 15 (fisco não aceita camadas do custo)
B46: RISCO 1: o fisco não aceita nenhuma camada do reflexo — resta apenas o custo original remanescente (cenário A da aba 'Cálculos da Operação').
B47: RISCO 2: o fisco não aceita a camada da mais-valia — o custo fiscal recua para a base contábil (custo original + reflexo do PL contábil da CNP), a mesma do CPC 19.
B49: Cenário de preço | C49: Preço de venda | D49: CPC 15 — custo integral | E49: RISCO 2 | F49: RISCO 1 | G49: Δ RISCO 2 | H49: Δ RISCO 1
B50: Custo fiscal considerado em cada hipótese | C50: – | D50: =$C$13 -> 645.6 | E50: =$C$13-$C$15 -> 632.4 | F50: =$C$14 -> 176.79814 | G50: =D50-E50 -> 13.2 | H50: =D50-F50 -> 468.80186
...

Sheet Conclusão
C4: Conclusão — CPC 15 × CPC 19
C5: 4 de setembro de 2026
B6: Custo do investimento para Savian e JVFJ
B8: O objetivo destes exemplos é ilustrar o impacto que a classificação da Transação como Combinação de Negócios (CPC 15) ou como Joint Operation (CPC 19) pode gerar no custo do investimento das Holdings e no caso de venda futura da participação remanescente de 60% da Embracon. Para isso, simulamos a venda com (i) preço inferior ao valor justo; (ii) preço idêntico ao valor justo; e (iii) preço superior ao valor justo — pela própria Holding ou pelas pessoas físicas (alíquota simplificada de 22,5% sobre o ganho de capital). Os números são meramente estimados e não devem ser utilizados para ilustrar custos e contingências reais. Todos os valores são vinculados às abas 'Premissas', 'Cálculos da Operação', 'CPC 19' e 'Alienação Futura (PJ x PF)'.
B10: CPC 15 | Combinação de Negócios
C11: PPA CNP | D11: Antes da Transação | E11: Depois do Cash-Out | F11: Δ | G11: IR 34% se negado | H11: Risco — 34% diferido
B12: Embracon (PL) | C12: – | D12: =Premissas!C19 -> 254 | E12: ='Cálculos da Operação'!I93 -> 176.79814 | F12: =E12-D12 -> -77.201856 | G12: – | H12: ■ Custo original remanescente — incontroverso (Δ = parcela baixada no cash-out).
B13: CNP (PL) | C13: =Premissas!C22 -> 800 | D13: 0 | E13: =E15-E12-E14 -> 455.60186 | F13: =E13-D13 -> 455.60186 | G13: =E13*Premissas!C28 -> 154.90463 | H13: ■ Reflexo do PL contábil da CNP (líquido da diluição) — neutralidade do MEP, risco limitado.
B14: CNP (AVJ) | C14: =Premissas!C37 -> 22 | D14: 0 | E14: =Premissas!C37*Premissas!C36 -> 13.2 | F14: =E14-D14 -> 13.2 | G14: =E14*Premissas!C28 -> 4.488 | H14: ■ Reflexo do valor justo (mais-valia) do PL da CNP — parcela mais exposta.
B15: Inv. Embracon | C15: =C13+C14 -> 822 | D15: =SUM(D12:D14) -> 254 | E15: ='Cálculos da Operação'!J93 -> 645.6 | F15: =E15-D15 -> 391.6 | G15: =SUM(G13:G14) -> 159.39263 | H15: Total = custo incrementado remanescente (aba 'Cálculos', cenário B); PPA = valor de mercado incorporado.
B16: Conferência: reflexo do PL contábil (linha CNP PL) × cálculo direto [PL CNP × 60% − diluição de 13,8% sobre o custo original × (1 − fração vendida)] | C16: =ROUND(E13-(Premissas!C22*Premissas!C36-Premissas!C19*Premissas!C25*(1-Premissas!C39)),6) -> 0
B18: CPC 19 | Joint Operation
C19: 100% JO | D19: 60% JO | E19: IR 34% diferido | F19: Risco — 34% diferido
B20: JO (PL) | C20: ='CPC 19'!C15 -> 1054 | D20: ='CPC 19'!D23 -> 632.4 | E20: – | F20: ■ Reflexo patrimonial (base contábil: PL da Embracon + PL contábil da CNP).
B21: AVJ JO | C21: ='CPC 19'!C16 -> 4901 | D21: ='CPC 19'!D24 -> 2940.6 | E21: ='CPC 19'!D25 -> 999.804 | F21: ■ AVJ de Embracon + CNP — IR de 34% 'carimbado', devido na venda em qualquer preço.
B22: Inv. JO | C22: ='CPC 19'!C14 -> 5955 | D22: ='CPC 19'!D26 -> 3573 | E22: =E21 -> 999.804 | F22: Total = 60% do valor justo da JO (aba 'CPC 19').
B24: Venda futura dos 60%
C26: CPC 15 | Combinação de Negócios | G26: CPC 19 | Joint Operation
C27: Preço | D27: Venda pela PJ | E27: Venda pela PF | G27: Preço | H27: Venda pela PJ | I27: Venda pela PF
C28: ='Alienação Futura (PJ x PF)'!C30 -> 1000 | D28: ='Alienação Futura (PJ x PF)'!D30 -> 120.496 | E28: ='Alienação Futura (PJ x PF)'!E30 -> 220.95 | G28: ='Alienação Futura (PJ x PF)'!C30 -> 1000 | H28: ='Alienação Futura (PJ x PF)'!F30 -> 999.804 | I28: ='Alienação Futura (PJ x PF)'!G30 -> 999.804
C29: ='Alienação Futura (PJ x PF)'!C31 -> 3573 | D29: ='Alienação Futura (PJ x PF)'!D31 -> 995.316 | E29: ='Alienação Futura (PJ x PF)'!E31 -> 799.875 | G29: ='Alienação Futura (PJ x PF)'!C31 -> 3573 | H29: ='Alienação Futura (PJ x PF)'!F31 -> 999.804 | I29: ='Alienação Futura (PJ x PF)'!G31 -> 999.804
C30: ='Alienação Futura (PJ x PF)'!C32 -> 5000 | D30: ='Alienação Futura (PJ x PF)'!D32 -> 1480.496 | E30: ='Alienação Futura (PJ x PF)'!E32 -> 1120.95 | G30: ='Alienação Futura (PJ x PF)'!C32 -> 5000 | H30: ='Alienação Futura (PJ x PF)'!F32 -> 1484.984 | I30: ='Alienação Futura (PJ x PF)'!G32 -> 1320.879
B31: Imposto (IRPJ/CSLL de 34% na Holding; IR de 22,5% na PF) na venda dos 60%, em R$ milhões — valores da aba 'Alienação Futura (PJ x PF)'.
B33: Conclusão executiva
B35: • CPC 15 é o cenário mais favorável às Holdings: o custo do investimento incorpora o reflexo da incorporação sem registro de passivo fiscal diferido, o imposto na venda futura acompanha o preço e existe a alternativa de venda pelas pessoas físicas à alíquota de 22,5%. O risco concentra-se na neutralidade do reflexo do PL contábil da CNP; com as premissas atuais a mais-valia é pequena e o imposto potencial sobre ela é residual.
B36: • CPC 19 elimina a discussão sobre o custo, mas ao preço de reconhecer ganho de AVJ sobre toda a JO — inclusive a Embracon, que no CPC 15 não é reavaliada — com IRPJ/CSLL de 34% carimbado e devido na venda em qualquer cenário de preço, sem a alternativa da PF. Além disso, o valor patrimonial das Holdings poderá subir ao valor justo (reconhecimento da CNP e da Embracon), com possível repercussão na base de cálculo do ITCMD, a depender do critério legal aplicável (tema não analisado neste material).
B37: • Na venda ao valor justo ou acima, a carga dos dois regimes é próxima (diferença = 34% da mais-valia da CNP); abaixo do valor justo, o CPC 19 é substancialmente mais oneroso. Se a tese de neutralidade do reflexo fosse integralmente afastada (RISCO 1), o CPC 15 passaria a ser mais oneroso que o CPC 19 nas vendas a partir do valor justo — daí a importância de documentar a tese e o laudo de avaliação (PPA).
B38: Ressalvas: valores ilustrativos em R$ milhões, data-base 30.06.2026, com as premissas da aba 'Premissas'. As Holdings estão no lucro presumido; na venda futura, a carga efetiva na PJ poderia ser reduzida com a opção pelo lucro real e a existência de prejuízos compensáveis. O custo das quotas nas PFs é premissa ilustrativa a confirmar. O material não avalia o ITCMD.

Sheet Dourada C. e A. SA
K2: Base das informações
B3: DOURADA COMERCIAL E AGROPECUARIA S/A | C3: Lucro Real | G3: 45627 | I3: Prejuízo Fiscal IRPJ | J3: 956469.6 | K3: -Excel LALUR 2024
B4: Ativos | D4: =SUM(D5+D11) -> 10218400 | E4: Passivos | G4: =SUM(G5+G10+G13) -> 10218400 | I4: Prejuízo Fiscal CSLL | J4: 956469.6 | K4: -Excel LALUR 2024
B5: Ativos circulantes | D5: =SUM(D6:D10) -> 1964054.2 | E5: Passivos circulantes | G5: =SUM(G6:G9) -> 132218.99 | J5: =SUM(J3+J4) -> 1912939.2
C6: Caixa e equivalentes de caixa | D6: 2 | F6: Empréstimos e financiamentos | G6: 0 | I6: Provisão p/ devedores duvidosos | J6: 34739.57 | K6: -Excel LALUR 2024
C7: Contas a receber | D7: 1072152.6 | F7: Fornecedores | G7: 102122.6
C8: Outras contas a receber (adiantamentos) | D8: 22442.37 | F8: Provisões trab/tribut | G8: 30096.39
C9: Títulos e valores mobiliários | D9: 326886.99 | F9: Adiantamento de clientes | G9: 0
C10: Impostos a compensar | D10: 542570.31 | E10: Passivos não circulantes | G10: =SUM(G11:G12) -> 32527.28
B11: Ativo Permanente | D11: =D13 -> 8254345.4 | F11: Dividendos | G11: 32527.28
C12: Investimentos | D12: 0 | F12: Empréstimos e financiamentos | G12: 0
C13: Imobilizado | D13: 8254345.4 | E13: Patrimônio líquido | G13: =SUM(G14:G17) -> 10053653
F14: Capital subscrito e integralizado | G14: 14139130
F15: Reserva de reavaliação | G15: 4562148.4
F16: Reserva de lucros (reserva legal) | G16: 48664.65
F17: Lucros/Prejuízos acumulados | G17: -8696289.6
B21: Incentivos Fiscais | C21: Base de Cálculo do Incentivo | D21: Limite de Dedução Individual | E21: Embasamento Legal
B22: Programa de Alimentação ao Trabalhador - PAT | C22: objetivo de melhorar as condições nutricionais e de qualidade de vida dos trabalhadores | D22: 4% do IRPJ devido ANTES ADCIONAL 10% | E22: Artigos 491 a 493, 504 a 507, 581 a 587 do RIR/99
B23: Doações aos Fundos dos Direitos da Criança e do Adolescente | C23: Doações efetivamente realizadas | D23: 1% do IRPJ devido ANTES ADICIONAL 10% | E23: Art. 591 do RIR/99
B24: Atividade Audiovisual | C24: Valores aplicados na aquisição de certificados de investimentos em projetos aprovados pelo Ministério da Cultura | D24: 3% do IRPJ devido ANTES ADICIONAL 10% | E24: Artigos 475 478, 484 a 488 do RIR/99
B25: LEI DE INCENTIVO A CULTURAL - ROUANET | C25: É a lei que institui o Programa Nacional de Apoio à Cultura - PRONAC | D25: 4% do IRPJ devido ANTES ADICIONAL 10% | E25: Base Legal: Lei 8.313/1991; Lei 9.874/1999; Decreto 3.000/1999; Instrução Normativa-SRF 267/2002 e Instrução Normativa-SRF 390/2004.
B26: FUNDO MUNICIPAL DO IDOSO - FMI | C26: doações efetuadas aos respectivos fundos municipais, estaduais e nacional. | D26: 1% do IRPJ devido ANTES ADCIONAL 10% | E26: LEI 12.213
B27: LEI DE INCENTIVO AO ESPORTE - LIE | C27: Objetiva principalmente incentivar o esporte de um modo geral. | D27: 1% do IRPJ devido ANTES ADICIONAL 10% | E27: LEI 11.438

Sheet Embracon Franchising
B3: EMBRACON FRANCHISING LTDA | C3: Lucro Presumido | G3: 45627 | L3: Excel: LALUR
B4: Ativos | D4: =SUM(D5+D9) -> 1167425.5 | E4: Passivos | G4: =G5+G7 -> 1167425.5
B5: Ativos circulantes | D5: =SUM(D6:D8) -> 383408.33 | E5: Passivos circulantes | G5: =G6 -> 17724.87
C6: Caixa e equivalentes de caixa | D6: 1 | F6: Fiscais e previdenciários | G6: 17724.87
C7: Titulos e Valores Mobiliários | D7: 317739.29 | E7: Patrimônio líquido | G7: =SUM(G8:G10) -> 1149700.6
C8: Outros créditos | D8: 65668.04 | F8: Capital subscrito e integralizado | G8: 1150000
B9: Ativo não circulante | D9: =D10 -> 784017.14 | F9: Capital a integralizar | G9: -200000
C10: Realizável a longo prazo - outros investimentos | D10: 784017.14 | F10: Reseva de Lucros | G10: 199700.6

Sheet Embrafisa Consul.
B3: EMBRAFISA CONSUL. EMPRE. CORRE. DE SEGU. E EMPREEND. IMOB. LTDA | C3: Lucro Presumido | G3: 45627 | H3: Balanço | L3: Excel: LALUR
B4: Ativos | D4: =SUM(D5+D12) -> 1.2237116e+08 | E4: Passivos | G4: =SUM(G5+G10) -> 1.2237116e+08
B5: Ativos circulantes | D5: =SUM(D6:D11) -> 14442337 | E5: Passivos circulantes | G5: =SUM(G6:G9) -> 21461592
C6: Caixa e equivalentes | D6: 2437109.3 | F6: Obrigações trib. | G6: 2494169
C7: clientes | D7: 7001150.1 | F7: Obrigações Trab. | G7: 558759.63
C8: adiantamentos | D8: 1273637.1 | F8: Contas a pagar | G8: 17920182
C9: Estoques | D9: 3718389.1 | F9: Previsão de adiantamento de clientes | G9: 488481.84
C10: Impostos a compensar | D10: 1006.72 | E10: Patrimônio líquido | G10: =SUM(G11:G12) -> 1.0090957e+08
C11: Ações Judiciais | D11: 11044.49 | F11: Capital subscrito e integralizado | G11: 86545880
B12: Ativo não circulante | D12: =SUM(D13:D14) -> 1.0792883e+08 | F12: Reserva de lucros | G12: 14363691
C13: Investimentos | D13: 46794804
C14: Imobilizado | D14: 61134022

Sheet GSJ
B3: COMPANHIA GSJ DE PART. | C3: Lucro Presumido | G3: 45627 | L3: Excel: LALUR
B4: Ativos | D4: =SUM(D5+D9) -> 1.0937994e+08 | E4: Passivos | G4: =SUM(G5+G9) -> 1.0937994e+08 | H4: GSJ Balanço
B5: Ativos circulantes | D5: =SUM(D6:D8) -> 820384.91 | E5: Passivos circulantes | G5: =SUM(G6:G8) -> 919578.08
C6: Caixa e equivalente | D6: 7 | F6: Fiscais e Previdenciarias | G6: 6731.94
C7: Titulos e valores mobiliarios | D7: 501276.83 | F7: Diversas | G7: 360471.48
C8: Outros creditos | D8: 319101.08 | F8: Dividendos a pagar | G8: 552374.66
B9: Ativo não circulante | D9: =SUM(D10:D12) -> 1.0855956e+08 | E9: Patrimônio líquido | G9: =SUM(G10:G14) -> 1.0846036e+08
C10: Participação societárias | D10: 64315927 | F10: Capital subscrito e integralizado | G10: 79875998
C11: Outros investimentos | D11: 21372770 | F11: Capital a integralizar | G11: -2603500
C12: Imobilizado | D12: 22870861 | F12: Reserva legal | G12: 1800035.9
F13: reserva de lucros | G13: 7330593.3
F14: Lucros/Prejuizos acumulados | G14: 22057238
