Workbook
Name __xlnm_Print_Area_1: #REF!

Sheet Organograma

Sheet Cálculos da Operação
G4: Cálculos tributários
G5: 21 de maio de 2025
B10: Premissas econômicas
B12: Patrimonio Liquido | E12: Informações Adicionais
B13: SAVIAN | C13: 127 | E13: Data-base dos balanços | I13: 30.06.2026
B14: Invest. Embracon | C14: 127 | E14: Unidade | I14: R$ milhões
E15: Participação das Partes CNP na incorporação (relação de troca) | I15: 0.138
B16: JVFJ | C16: 127 | E16: Participação-alvo final das Partes na CNPH | I16: 0.4
B17: Invest. Embracon | C17: 127 | E17: IRPJ/CSLL — ganho de capital PJ | I17: 0.34
B19: EMBRACON | C19: 254
B20: SAVIAN | C20: =C16/C19 -> 0.5
B21: JVFJ | C21: =C16/C19 -> 0.5
B23: CNPH | C23: 800
B24: Valor de Mercado CNPH | C24: 822
B26: 1) Incorporação CNPH
B28: Participação Societária (Embracon)
C29: Antes | D29: Após Inc
B30: SAVIAN | C30: 0.5 | D30: =C30*(1-I15) -> 0.431
B31: JVFJ | C31: 0.5 | D31: =C31*(1-I15) -> 0.431
B32: CNP (ações novas) | C32: - | D32: =I15 -> 0.138
D33: =SUM(D30:D32) -> 1
B35: Embracon - Incorporação do Acervo
B36: EMBRACON | C36: =C19 -> 254 | D36: =C36/C$38 -> 0.23605948
B37: CNPH | C37: =C24 -> 822 | D37: =C37/C$38 -> 0.76394052
B38: (=) Total | C38: =C36+C37 -> 1076 | D38: =D36+D37 -> 1
B40: PL Embracon (pós inc) | C40: =C41+C42+C43 -> 1076
B41: SAVIAN | C41: =D30*C38 -> 463.756
B42: JVFJ | C42: =D31*C38 -> 463.756
B43: CNP | C43: =D32*C38 -> 148.488
B45: Reflexo nas Holdings (MEP) - Custo de Investimento | H45: Lançamentos Contábeis (Holdings)
D46: SAVIAN | E46: JVFJ | F46: Total | I46: Débitos | J46: Crédito
B47: Custo Original (Investimento anterior) | D47: =C14 -> 127 | E47: =C14 -> 127 | F47: =D47+E47 -> 254 | H47: Reflexo da Incorporação | I47: =D48 -> 411
B48: (+) Incorporação base | D48: =C37/2 -> 411 | E48: =C37/2 -> 411 | F48: =D48+E48 -> 822 | H48: Perda de diluição | J48: =D49 -> -74.244
B49: (-) Diluição (13,8%) | D49: =-(D47+D48)*I15 -> -74.244 | E49: =-(E47+E48)*I15 -> -74.244 | F49: =D49+E49 -> -148.488 | H49: (=) Efeito Líquido do Investimento | J49: =I47+J48 -> 336.756
B50: (=) Parcela liquida incorporada | D50: =D48+D49 -> 336.756 | E50: =E48+E49 -> 336.756 | F50: =D50+E50 -> 673.512
B52: Custo do Investimento Incrementado (Alternativa)
B53: (=) Custo Incrementado | D53: 2 x 463,75 -> | E53: =2*(D54+D55) -> 927.512
B54: Custo Original | D54: =C14 -> 127 | E54: =C17 -> 127
B55: Acervo liquido incorporado | D55: =D50 -> 336.756 | E55: =E50 -> 336.756
B58: 2) Cash-out - Simultânea
...

Sheet Segregação de Risco
G4: Segregação de risco
G5: 4 de setembro de 2026
B8: Segregação de Risco — Custo do Investimento das Holdings (CPC 15 × CPC 19)
B10: O que esta aba analisa
B11: Esta aba complementa a aba 'Cálculos da Operação'. Lá se apura o custo do investimento das Holdings (Savian e JVFJ) na Embracon após a incorporação da CNP e o imposto do cash-out, comparando o custo original (cenário A) com o custo incrementado pelo reflexo da incorporação (cenário B). Aqui respondemos a três perguntas que decorrem daquele resultado: (1) de que camadas é formado o custo incrementado e qual o risco fiscal de cada uma, no enquadramento da operação como combinação de negócios (CPC 15); (2) o que muda se a operação for enquadrada como operação em conjunto (CPC 19), em que as Holdings reconhecem 60% do valor justo de toda a JO e um imposto diferido 'carimbado' de 34%; e (3) quanto de imposto seria devido em uma venda futura dos 60%, pela Holding (PJ) ou pelas pessoas físicas (PF), em cada cenário. Os valores partem das premissas da aba 'Cálculos da Operação' (relacionadas abaixo) e estão em R$ milhões; as premissas específicas de cada bloco são indicadas no próprio bloco.
B13: Informações utilizadas (fonte: aba 'Cálculos da Operação', salvo indicação em contrário)
B14: Informação | C14: Valor | D14: Origem / observação
B15: Data-base dos balanços | C15: 30.06.2026 | D15: Balanços das companhias utilizados na aba 'Cálculos da Operação'
B16: Unidade | C16: R$ milhões
B17: Participação das Partes CNP na incorporação (relação de troca) | C17: ='Cálculos da Operação'!I15 -> 0.138 | D17: Ações novas emitidas pela Embracon às Partes CNP na incorporação
B18: Participação-alvo final das Partes CNP | C18: ='Cálculos da Operação'!I16 -> 0.4 | D18: Após o cash-out (compra de 26,2% das Holdings)
B19: Participação final das famílias (Savian + JVFJ) | C19: =1-C18 -> 0.6 | D19: Posição remanescente das Holdings, objeto da venda futura simulada no bloco 3
B20: Fração do investimento das Holdings alienada no cash-out | C20: ='Cálculos da Operação'!D69 -> 0.30394432 | D20: 13,1% vendidos ÷ 43,1% detidos por Holding — mesmo critério de alocação de custo da aba 'Cálculos da Operação'
B21: IRPJ/CSLL — ganho de capital PJ | C21: ='Cálculos da Operação'!I17 -> 0.34 | D21: Alíquota combinada aplicada às Holdings
B22: PL contábil da Embracon (antes da incorporação) | C22: ='Cálculos da Operação'!C19 -> 254 | D22: PL da Embracon; corresponde ao custo original das Holdings
B23: Custo original do investimento das Holdings (Savian + JVFJ) | C23: ='Cálculos da Operação'!F47 -> 254 | D23: Investimento original em Embracon: 127 de cada Holding
B24: PL contábil da CNP | C24: ='Cálculos da Operação'!C23 -> 800 | D24: Patrimônio líquido contábil da CNP incorporada
B25: Valor de mercado da CNP (valor pelo qual o acervo é incorporado no CPC 15 — PPA) | C25: ='Cálculos da Operação'!C24 -> 822 | D25: Valor de mercado adotado na aba 'Cálculos da Operação'
B26: Mais-valia da CNP (valor de mercado − PL contábil) | C26: =C25-C24 -> 22 | D26: Camada de avaliação a valor justo (AVJ) que o CPC 15 leva ao custo das Holdings via MEP
B28: 1) CPC 15 — Combinação de Negócios: de que é feito o custo do investimento das Holdings e onde está o risco
B30: Na combinação de negócios (CPC 15) a Embracon adquire o controle do negócio da CNP: o acervo da CNP entra pelo valor de mercado apurado em laudo (PPA) e o patrimônio da própria Embracon não é reavaliado. Nas Holdings, o investimento sobe pelo método de equivalência patrimonial (MEP): ao custo original soma-se o reflexo do acervo incorporado, deduzida a perda pela diluição de 13,8%. O quadro abre esse custo em camadas porque cada camada tem um risco fiscal diferente. O custo original é incontroverso. O reflexo do PL contábil da CNP depende da tese de que o resultado de equivalência é neutro para fins fiscais também na alienação futura (art. 33, §2º, do DL 1.598/77; precedente WTorre). O reflexo da mais-valia (valor de mercado acima do PL contábil) é a parcela mais exposta, por corresponder a uma avaliação a valor justo que nunca foi tributada. As colunas mostram o valor a 100% (PL da Embracon após a incorporação), a parcela das Holdings logo após a incorporação (86,2%) e a parcela remanescente após o cash-out (60%).
B32: 1.1 Composição do custo do investimento das Holdings, por camada
B33: Camada do custo | C33: PL Embracon pós-incorporação (100%) | D33: Holdings pós-incorporação (86,2%) | E33: Holdings após o cash-out (60%) | F33: Baixa no cash-out | G33: IR potencial (34%) sobre a camada | H33: Leitura de risco
B34: Custo original (PL contábil da Embracon) | C34: =C22 -> 254 | D34: =C23 -> 254 | E34: =D34*(1-$C$20) -> 176.79814 | F34: =E34-D34 -> -77.201856 | G34: – | H34: Incontroverso: custo histórico das ações; é o custo do cenário A da aba 'Cálculos da Operação'.
B35: (−) Perda por diluição de 13,8% sobre o custo original | C35: – | D35: =-D34*$C$17 -> -35.052 | E35: =D35*(1-$C$20) -> -24.398144 | F35: =E35-D35 -> 10.653856 | G35: =E35*$C$21 -> -8.2953689 | H35: Perda de MEP por variação de percentual: fiscalmente neutra (art. 33, §2º, DL 1.598/77); reduz o reflexo contábil (e o IR potencial da camada seguinte), não o custo fiscal original.
B36: Reflexo do PL contábil da CNP | C36: =C24 -> 800 | D36: =C36*(1-$C$17) -> 689.6 | E36: =C36*$C$19 -> 480 | F36: =E36-D36 -> -209.6 | G36: =E36*$C$21 -> 163.2 | H36: Risco limitado: reflexo MEP do PL incorporado a valor contábil; sustenta-se na tese de neutralidade do MEP (WTorre), com precedentes CARF 2024 em sentido contrário.
B37: Reflexo da mais-valia da CNP (AVJ do PPA) | C37: =C26 -> 22 | D37: =C37*(1-$C$17) -> 18.964 | E37: =C37*$C$19 -> 13.2 | F37: =E37-D37 -> -5.764 | G37: =E37*$C$21 -> 4.488 | H37: Camada mais exposta: valor de mercado acima do PL contábil, nunca tributado; é a parcela que o fisco tenderia a atacar primeiro.
B38: (=) Custo do investimento das Holdings | C38: =SUM(C34:C37) -> 1076 | D38: =SUM(D34:D37) -> 927.512 | E38: =SUM(E34:E37) -> 645.6 | F38: =SUM(F34:F37) -> -281.912 | G38: =SUM(G35:G37) -> 159.39263 | H38: Total das camadas: após a incorporação = custo incrementado; após o cash-out = custo remanescente do cenário B (aba 'Cálculos da Operação').
B39: Conferência com a aba 'Cálculos da Operação' (diferença; 'ok' = zero) | C39: – | D39: =ROUND(D38-'Cálculos da Operação'!E53,6) -> 0 | E39: =ROUND(E38-'Cálculos da Operação'!J89,6) -> 0 | F39: =ROUND(F38+'Cálculos da Operação'!J82,6) -> 0 | G39: – | H39: D = custo incrementado (E53) · E = custo remanescente do cenário B (J89) · F = custo alocado no cash-out (J82)
B41: 1.2 Leitura: quanto do custo remanescente é seguro e quanto está em discussão (após o cash-out)
B42: Parcela do custo após o cash-out | C42: Valor | D42: % do custo | E42: IR potencial (34%) | F42: Comentário
B43: Custo fiscal incontroverso (custo original remanescente = cenário A) | C43: =E34 -> 176.79814 | D43: =C43/$C$46 -> 0.2738509 | E43: – | F43: Custo aceito em qualquer leitura; é o cenário mais conservador da aba 'Cálculos da Operação'.
B44: Reflexo do PL contábil da CNP, líquido da perda por diluição (risco limitado) | C44: =E36+E35 -> 455.60186 | D44: =C44/$C$46 -> 0.705703 | E44: =C44*$C$21 -> 154.90463 | F44: Depende da tese de neutralidade do reflexo de MEP; o IR só seria devido se o fisco tributar o reflexo na alienação.
B45: Reflexo da mais-valia da CNP (maior exposição) | C45: =E37 -> 13.2 | D45: =C45/$C$46 -> 0.020446097 | E45: =C45*$C$21 -> 4.488 | F45: Parcela do PPA levada ao custo; com as premissas atuais é pequena, porque o valor de mercado da CNP está próximo do seu PL contábil.
B46: (=) Custo após o cash-out (cenário B) — incremento em discussão = linhas 2 + 3 | C46: =SUM(C43:C45) -> 645.6 | D46: =SUM(D43:D45) -> 1 | E46: =SUM(E44:E45) -> 159.39263 | F46: O incremento em discussão (C44 + C45) é exatamente a diferença de custo remanescente entre os cenários B e A da aba 'Cálculos da Operação'.
B47: Conferência: incremento em discussão − Δ custo remanescente da aba 'Cálculos da Operação' (K89) | C47: =ROUND(C44+C45-'Cálculos da Operação'!K89,6) -> 0
B49: 2) CPC 19 — Joint Operation: reconhecimento de 60% do valor justo da JO e imposto diferido 'carimbado'
B51: Na operação em conjunto (CPC 19), leitura sustentada pela Deloitte a partir dos vetos qualificados da CNP, as Holdings deixam de avaliar o investimento pelo MEP e passam a reconhecer diretamente a sua parcela (60%) dos ativos e passivos da JO — Embracon e CNP — a valor justo. Isso inclui o valor justo da própria Embracon, que no CPC 15 não é reavaliada. O ganho de avaliação a valor justo (AVJ) não é tributado no reconhecimento, desde que controlado em subconta (arts. 13 e 14 da Lei 12.973/14), mas fica 'carimbado': o IRPJ/CSLL de 34% sobre o AVJ é devido quando o investimento for realizado (venda), qualquer que seja o preço e independentemente de quem venda. O bloco usa como valor justo da Embracon o enterprise value do Acordo de Investimento (premissa editável abaixo) e, para a CNP, o valor de mercado já adotado na aba 'Cálculos da Operação'.
B53: 2.1 Premissa adicional deste bloco
B54: Valor justo da Embracon — enterprise value do Acordo de Investimento (data-base 31.12.2024) | C54: 5133 | D54: Premissa editável. No CPC 15 a Embracon não é reavaliada; no CPC 19 o seu valor justo entra integralmente no investimento das Holdings.
...

Sheet Dourada C. e A. SA
K2: Base das informações
B3: DOURADA COMERCIAL E AGROPECUARIA S/A | C3: Lucro Real | G3: 45627 | I3: Prejuízo Fiscal IRPJ | J3: 956469.6 | K3: -Excel LALUR 2024
B4: Ativos | D4: =SUM(D5+D11) -> 10218400 | E4: Passivos | G4: =SUM(G5+G10+G13) -> 10218400 | I4: Prejuízo Fiscal CSLL | J4: 956469.6 | K4: -Excel LALUR 2024
B5: Ativos circulantes | D5: =SUM(D6:D10) -> 1964054.2 | E5: Passivos circulantes | G5: =SUM(G6:G9) -> 132218.99 | J5: =SUM(J3+J4) -> 1912939.2
C6: Caixa e equivalentes de caixa | D6: 2 | F6: Empréstimos e financiamentos | G6: 0 | I6: Provisão p/ devedores duvidosos | J6: 34739.57 | K6: -Excel LALUR 2024
C7: Contas a receber | D7: 1072152.6 | F7: Fornecedores | G7: 102122.6
C8: Outras contas a receber (adiantamentos) | D8: 22442.37 | F8: Provisões trab/tribut | G8: 30096.39
C9: Títulos e valores mobiliários | D9: 326886.99 | F9: Adiantamento de clientes | G9: 0
C10: Impostos a compensar | D10: 542570.31 | E10: Passivos não circulantes | G10: =SUM(G11:G12) -> 32527.28
B11: Ativo Permanente | D11: =D13 -> 8254345.4 | F11: Dividendos | G11: 32527.28
C12: Investimentos | D12: 0 | F12: Empréstimos e financiamentos | G12: 0
C13: Imobilizado | D13: 8254345.4 | E13: Patrimônio líquido | G13: =SUM(G14:G17) -> 10053653
F14: Capital subscrito e integralizado | G14: 14139130
F15: Reserva de reavaliação | G15: 4562148.4
F16: Reserva de lucros (reserva legal) | G16: 48664.65
F17: Lucros/Prejuízos acumulados | G17: -8696289.6
B21: Incentivos Fiscais | C21: Base de Cálculo do Incentivo | D21: Limite de Dedução Individual | E21: Embasamento Legal
B22: Programa de Alimentação ao Trabalhador - PAT | C22: objetivo de melhorar as condições nutricionais e de qualidade de vida dos trabalhadores | D22: 4% do IRPJ devido ANTES ADCIONAL 10% | E22: Artigos 491 a 493, 504 a 507, 581 a 587 do RIR/99
B23: Doações aos Fundos dos Direitos da Criança e do Adolescente | C23: Doações efetivamente realizadas | D23: 1% do IRPJ devido ANTES ADICIONAL 10% | E23: Art. 591 do RIR/99
B24: Atividade Audiovisual | C24: Valores aplicados na aquisição de certificados de investimentos em projetos aprovados pelo Ministério da Cultura | D24: 3% do IRPJ devido ANTES ADICIONAL 10% | E24: Artigos 475 478, 484 a 488 do RIR/99
B25: LEI DE INCENTIVO A CULTURAL - ROUANET | C25: É a lei que institui o Programa Nacional de Apoio à Cultura - PRONAC | D25: 4% do IRPJ devido ANTES ADICIONAL 10% | E25: Base Legal: Lei 8.313/1991; Lei 9.874/1999; Decreto 3.000/1999; Instrução Normativa-SRF 267/2002 e Instrução Normativa-SRF 390/2004.
B26: FUNDO MUNICIPAL DO IDOSO - FMI | C26: doações efetuadas aos respectivos fundos municipais, estaduais e nacional. | D26: 1% do IRPJ devido ANTES ADCIONAL 10% | E26: LEI 12.213
B27: LEI DE INCENTIVO AO ESPORTE - LIE | C27: Objetiva principalmente incentivar o esporte de um modo geral. | D27: 1% do IRPJ devido ANTES ADICIONAL 10% | E27: LEI 11.438

Sheet Embracon Franchising
B3: EMBRACON FRANCHISING LTDA | C3: Lucro Presumido | G3: 45627 | L3: Excel: LALUR
B4: Ativos | D4: =SUM(D5+D9) -> 1167425.5 | E4: Passivos | G4: =G5+G7 -> 1167425.5
B5: Ativos circulantes | D5: =SUM(D6:D8) -> 383408.33 | E5: Passivos circulantes | G5: =G6 -> 17724.87
C6: Caixa e equivalentes de caixa | D6: 1 | F6: Fiscais e previdenciários | G6: 17724.87
C7: Titulos e Valores Mobiliários | D7: 317739.29 | E7: Patrimônio líquido | G7: =SUM(G8:G10) -> 1149700.6
C8: Outros créditos | D8: 65668.04 | F8: Capital subscrito e integralizado | G8: 1150000
B9: Ativo não circulante | D9: =D10 -> 784017.14 | F9: Capital a integralizar | G9: -200000
C10: Realizável a longo prazo - outros investimentos | D10: 784017.14 | F10: Reseva de Lucros | G10: 199700.6

Sheet Embrafisa Consul.
B3: EMBRAFISA CONSUL. EMPRE. CORRE. DE SEGU. E EMPREEND. IMOB. LTDA | C3: Lucro Presumido | G3: 45627 | H3: Balanço | L3: Excel: LALUR
B4: Ativos | D4: =SUM(D5+D12) -> 1.2237116e+08 | E4: Passivos | G4: =SUM(G5+G10) -> 1.2237116e+08
B5: Ativos circulantes | D5: =SUM(D6:D11) -> 14442337 | E5: Passivos circulantes | G5: =SUM(G6:G9) -> 21461592
C6: Caixa e equivalentes | D6: 2437109.3 | F6: Obrigações trib. | G6: 2494169
C7: clientes | D7: 7001150.1 | F7: Obrigações Trab. | G7: 558759.63
C8: adiantamentos | D8: 1273637.1 | F8: Contas a pagar | G8: 17920182
C9: Estoques | D9: 3718389.1 | F9: Previsão de adiantamento de clientes | G9: 488481.84
C10: Impostos a compensar | D10: 1006.72 | E10: Patrimônio líquido | G10: =SUM(G11:G12) -> 1.0090957e+08
C11: Ações Judiciais | D11: 11044.49 | F11: Capital subscrito e integralizado | G11: 86545880
B12: Ativo não circulante | D12: =SUM(D13:D14) -> 1.0792883e+08 | F12: Reserva de lucros | G12: 14363691
C13: Investimentos | D13: 46794804
C14: Imobilizado | D14: 61134022

Sheet GSJ
B3: COMPANHIA GSJ DE PART. | C3: Lucro Presumido | G3: 45627 | L3: Excel: LALUR
B4: Ativos | D4: =SUM(D5+D9) -> 1.0937994e+08 | E4: Passivos | G4: =SUM(G5+G9) -> 1.0937994e+08 | H4: GSJ Balanço
B5: Ativos circulantes | D5: =SUM(D6:D8) -> 820384.91 | E5: Passivos circulantes | G5: =SUM(G6:G8) -> 919578.08
C6: Caixa e equivalente | D6: 7 | F6: Fiscais e Previdenciarias | G6: 6731.94
C7: Titulos e valores mobiliarios | D7: 501276.83 | F7: Diversas | G7: 360471.48
C8: Outros creditos | D8: 319101.08 | F8: Dividendos a pagar | G8: 552374.66
B9: Ativo não circulante | D9: =SUM(D10:D12) -> 1.0855956e+08 | E9: Patrimônio líquido | G9: =SUM(G10:G14) -> 1.0846036e+08
C10: Participação societárias | D10: 64315927 | F10: Capital subscrito e integralizado | G10: 79875998
C11: Outros investimentos | D11: 21372770 | F11: Capital a integralizar | G11: -2603500
C12: Imobilizado | D12: 22870861 | F12: Reserva legal | G12: 1800035.9
F13: reserva de lucros | G13: 7330593.3
F14: Lucros/Prejuizos acumulados | G14: 22057238
