Workbook
Name __xlnm_Print_Area_1: #REF!

Sheet Organograma

Sheet Cálculos da Operação
E4: Cálculo da Operação e Ganho de Capital
B10: Premissas econômicas
B12: Patrimonio Liquido | E12: Informações Adicionais
B13: SAVIAN | C13: 127 | E13: Data-base dos balanços | I13: 30.06.2026
B14: Invest. Embracon | C14: 127 | E14: Unidade | I14: R$ milhões
E15: Participação das Partes CNP na incorporação (relação de troca) | I15: 0.138
B16: JVFJ | C16: 127 | E16: Participação-alvo final das Partes na CNPH | I16: 0.4
B17: Invest. Embracon | C17: 127 | E17: IRPJ/CSLL — ganho de capital PJ | I17: 0.34
B19: EMBRACON | C19: 254
B20: SAVIAN | C20: =C16/C19 -> 0.5
B21: JVFJ | C21: =C16/C19 -> 0.5
B23: CNP | C23: 800
B24: Valor de Mercado CNP | C24: 822
B26: CPC 15 — Combinação de Negócios
B28: 1) Incorporação CNPH
B30: Participação Societária (Embracon)
C31: Antes | D31: Após Inc
B32: SAVIAN | C32: 0.5 | D32: =C32*(1-I15) -> 0.431
B33: JVFJ | C33: 0.5 | D33: =C33*(1-I15) -> 0.431
B34: CNPH (ações novas) | C34: - | D34: =I15 -> 0.138
D35: =SUM(D32:D34) -> 1
B37: Embracon - Incorporação do Acervo
B38: EMBRACON | C38: =C19 -> 254 | D38: =C38/C$40 -> 0.23605948
B39: CNP | C39: =C24 -> 822 | D39: =C39/C$40 -> 0.76394052
B40: (=) Total | C40: =C38+C39 -> 1076 | D40: =D38+D39 -> 1
B42: PL Embracon (pós inc) | C42: =C43+C44+C45 -> 1076
B43: SAVIAN | C43: =D32*C40 -> 463.756
B44: JVFJ | C44: =D33*C40 -> 463.756
B45: CNP | C45: =D34*C40 -> 148.488
B47: Reflexo nas Holdings (MEP) - Custo de Investimento | H47: Lançamentos Contábeis (Holdings)
D48: SAVIAN | E48: JVFJ | F48: Total | I48: Débitos | J48: Crédito
B49: Custo Original (Investimento anterior) | D49: =C14 -> 127 | E49: =C14 -> 127 | F49: =D49+E49 -> 254 | H49: Reflexo da Incorporação | I49: =D50 -> 411
B50: (+) Incorporação base | D50: =C39/2 -> 411 | E50: =C39/2 -> 411 | F50: =D50+E50 -> 822 | H50: Perda de diluição | J50: =D51 -> -74.244
B51: (-) Diluição (13,8%) | D51: =-(D49+D50)*I15 -> -74.244 | E51: =-(E49+E50)*I15 -> -74.244 | F51: =D51+E51 -> -148.488 | H51: (=) Efeito Líquido do Investimento | J51: =I49+J50 -> 336.756
B52: (=) Parcela liquida incorporada | D52: =D50+D51 -> 336.756 | E52: =E50+E51 -> 336.756 | F52: =D52+E52 -> 673.512
B54: Custo do Investimento Incrementado (Alternativa)
B55: (=) Custo Incrementado | D55: 2 x 463,75 -> | E55: =2*(D56+D57) -> 927.512
B56: Custo Original | D56: =C14 -> 127 | E56: =C17 -> 127
B57: Acervo liquido incorporado | D57: =D52 -> 336.756 | E57: =E52 -> 336.756
B60: 2) Cash-out - Simultânea
...

Sheet Alienação Futura (PJ x PF)
C3: Alienação Futura - Analise dos Cenários
B7: Informação | C7: Valor
B8: Participação das Partes CNP na incorporação (relação de troca) | C8: ='Cálculos da Operação'!I15 -> 0.138
B9: Participação-alvo final das Partes CNP | C9: ='Cálculos da Operação'!I16 -> 0.4
B10: Participação final das famílias (Savian + JVFJ) | C10: =1-C9 -> 0.6
B11: Fração do investimento das Holdings alienada no cash-out | C11: ='Cálculos da Operação'!D71 -> 0.30394432
B12: IRPJ/CSLL — ganho de capital PJ | C12: ='Cálculos da Operação'!I17 -> 0.34
B13: PL contábil da Embracon (antes da incorporação) | C13: ='Cálculos da Operação'!C19 -> 254
B14: Custo original do investimento das Holdings (Savian + JVFJ) | C14: ='Cálculos da Operação'!F49 -> 254
B15: PL contábil da CNP | C15: ='Cálculos da Operação'!C23 -> 800
B16: Valor de mercado da CNP (valor pelo qual o acervo é incorporado no CPC 15 — PPA) | C16: ='Cálculos da Operação'!C24 -> 822
B17: Mais-valia da CNP | C17: =C16-C15 -> 22
B19: 1) Custo do Investimento das Holdings (CPC 15 × CPC 19)
B21: CPC 15 — Combinação de Negócios
B23: Composição do custo do investimento das Holdings
B24: Camada do custo | C24: PL Embracon (pós inc) | D24: Holdings (pós inc) | E24: Holdings após o cash-out | F24: Baixa no cash-out | G24: IR (34%)
B25: Custo original (PL contábil da Embracon) | C25: =C13 -> 254 | D25: =C14 -> 254 | E25: =D25*(1-$C$11) -> 176.79814 | F25: =E25-D25 -> -77.201856 | G25: –
B26: (−) Perda por diluição de 13,8% sobre o custo original | C26: – | D26: =-D25*$C$8 -> -35.052 | E26: =D26*(1-$C$11) -> -24.398144 | F26: =E26-D26 -> 10.653856 | G26: =E26*$C$12 -> -8.2953689
B27: Reflexo do PL contábil da CNP | C27: =C15 -> 800 | D27: =C27*(1-$C$8) -> 689.6 | E27: =C27*$C$10 -> 480 | F27: =E27-D27 -> -209.6 | G27: =E27*$C$12 -> 163.2
B28: Reflexo da mais-valia da CNP (AVJ do PPA) | C28: =C17 -> 22 | D28: =C28*(1-$C$8) -> 18.964 | E28: =C28*$C$10 -> 13.2 | F28: =E28-D28 -> -5.764 | G28: =E28*$C$12 -> 4.488
B29: (=) Custo do investimento das Holdings | C29: =SUM(C25:C28) -> 1076 | D29: =SUM(D25:D28) -> 927.512 | E29: =SUM(E25:E28) -> 645.6 | F29: =SUM(F25:F28) -> -281.912 | G29: =SUM(G26:G28) -> 159.39263
B31: Custo remanescente após o cash-out
B32: Parcela do custo após o cash-out | C32: Valor | D32: % do custo | E32: IR potencial (34%)
B33: Custo fiscal original | C33: =E25 -> 176.79814 | D33: =C33/$C$36 -> 0.2738509 | E33: –
B34: Reflexo do PL contábil da CNP (pós diluição) | C34: =E27+E26 -> 455.60186 | D34: =C34/$C$36 -> 0.705703 | E34: =C34*$C$12 -> 154.90463
B35: Reflexo da mais-valia da CNP | C35: =E28 -> 13.2 | D35: =C35/$C$36 -> 0.020446097 | E35: =C35*$C$12 -> 4.488
B36: (=) Custo após o cash-out (com incremento) | C36: =SUM(C33:C35) -> 645.6 | D36: =SUM(D33:D35) -> 1 | E36: =SUM(E34:E35) -> 159.39263
B38: CPC 19 — Joint Operation
B40: Avaliação a Valor Justo
B41: VJ da Embracon | C41: 5133
B42: VJ CNP | C42: =C16 -> 822
B44: Investimento das Holdings na JO (60% - pós cash-out)
B45: Componente | C45: 100% da JO | D45: 60% (Holdings)
B46: Valor justo da Embracon | C46: =C41 -> 5133 | D46: =C46*$C$10 -> 3079.8
B47: Valor justo da CNP | C47: =C42 -> 822 | D47: =C47*$C$10 -> 493.2
B48: (=) Valor justo total | C48: =C46+C47 -> 5955 | D48: =D46+D47 -> 3573 | E48: Custo do investimento das Holdings no CPC 19
B50: (−) Base contábil (PL Embracon + PL CNP) | C50: =C13+C15 -> 1054 | D50: =C50*$C$10 -> 632.4
B51: (=) Ganho de AVJ | C51: =C48-C50 -> 4901 | D51: =D48-D50 -> 2940.6 | E51: Tributação diferida (subconta — arts. 13 e 14, Lei 12.973/14)
B53: Tributação do Passivo fiscal diferido | C53: =C51*$C$12 -> 1666.34 | D53: =D51*$C$12 -> 999.804 | E53: Devido na realização do investimento (venda)
B55: Custo de Investimento nas Holdings - CPC 19 | C55: =D48 -> 3573
...

Sheet Dourada C. e A. SA
K2: Base das informações
B3: DOURADA COMERCIAL E AGROPECUARIA S/A | C3: Lucro Real | G3: 45627 | I3: Prejuízo Fiscal IRPJ | J3: 956469.6 | K3: -Excel LALUR 2024
B4: Ativos | D4: =SUM(D5+D11) -> 10218400 | E4: Passivos | G4: =SUM(G5+G10+G13) -> 10218400 | I4: Prejuízo Fiscal CSLL | J4: 956469.6 | K4: -Excel LALUR 2024
B5: Ativos circulantes | D5: =SUM(D6:D10) -> 1964054.2 | E5: Passivos circulantes | G5: =SUM(G6:G9) -> 132218.99 | J5: =SUM(J3+J4) -> 1912939.2
C6: Caixa e equivalentes de caixa | D6: 2 | F6: Empréstimos e financiamentos | G6: 0 | I6: Provisão p/ devedores duvidosos | J6: 34739.57 | K6: -Excel LALUR 2024
C7: Contas a receber | D7: 1072152.6 | F7: Fornecedores | G7: 102122.6
C8: Outras contas a receber (adiantamentos) | D8: 22442.37 | F8: Provisões trab/tribut | G8: 30096.39
C9: Títulos e valores mobiliários | D9: 326886.99 | F9: Adiantamento de clientes | G9: 0
C10: Impostos a compensar | D10: 542570.31 | E10: Passivos não circulantes | G10: =SUM(G11:G12) -> 32527.28
B11: Ativo Permanente | D11: =D13 -> 8254345.4 | F11: Dividendos | G11: 32527.28
C12: Investimentos | D12: 0 | F12: Empréstimos e financiamentos | G12: 0
C13: Imobilizado | D13: 8254345.4 | E13: Patrimônio líquido | G13: =SUM(G14:G17) -> 10053653
F14: Capital subscrito e integralizado | G14: 14139130
F15: Reserva de reavaliação | G15: 4562148.4
F16: Reserva de lucros (reserva legal) | G16: 48664.65
F17: Lucros/Prejuízos acumulados | G17: -8696289.6
B21: Incentivos Fiscais | C21: Base de Cálculo do Incentivo | D21: Limite de Dedução Individual | E21: Embasamento Legal
B22: Programa de Alimentação ao Trabalhador - PAT | C22: objetivo de melhorar as condições nutricionais e de qualidade de vida dos trabalhadores | D22: 4% do IRPJ devido ANTES ADCIONAL 10% | E22: Artigos 491 a 493, 504 a 507, 581 a 587 do RIR/99
B23: Doações aos Fundos dos Direitos da Criança e do Adolescente | C23: Doações efetivamente realizadas | D23: 1% do IRPJ devido ANTES ADICIONAL 10% | E23: Art. 591 do RIR/99
B24: Atividade Audiovisual | C24: Valores aplicados na aquisição de certificados de investimentos em projetos aprovados pelo Ministério da Cultura | D24: 3% do IRPJ devido ANTES ADICIONAL 10% | E24: Artigos 475 478, 484 a 488 do RIR/99
B25: LEI DE INCENTIVO A CULTURAL - ROUANET | C25: É a lei que institui o Programa Nacional de Apoio à Cultura - PRONAC | D25: 4% do IRPJ devido ANTES ADICIONAL 10% | E25: Base Legal: Lei 8.313/1991; Lei 9.874/1999; Decreto 3.000/1999; Instrução Normativa-SRF 267/2002 e Instrução Normativa-SRF 390/2004.
B26: FUNDO MUNICIPAL DO IDOSO - FMI | C26: doações efetuadas aos respectivos fundos municipais, estaduais e nacional. | D26: 1% do IRPJ devido ANTES ADCIONAL 10% | E26: LEI 12.213
B27: LEI DE INCENTIVO AO ESPORTE - LIE | C27: Objetiva principalmente incentivar o esporte de um modo geral. | D27: 1% do IRPJ devido ANTES ADICIONAL 10% | E27: LEI 11.438

Sheet Embracon Franchising
B3: EMBRACON FRANCHISING LTDA | C3: Lucro Presumido | G3: 45627 | L3: Excel: LALUR
B4: Ativos | D4: =SUM(D5+D9) -> 1167425.5 | E4: Passivos | G4: =G5+G7 -> 1167425.5
B5: Ativos circulantes | D5: =SUM(D6:D8) -> 383408.33 | E5: Passivos circulantes | G5: =G6 -> 17724.87
C6: Caixa e equivalentes de caixa | D6: 1 | F6: Fiscais e previdenciários | G6: 17724.87
C7: Titulos e Valores Mobiliários | D7: 317739.29 | E7: Patrimônio líquido | G7: =SUM(G8:G10) -> 1149700.6
C8: Outros créditos | D8: 65668.04 | F8: Capital subscrito e integralizado | G8: 1150000
B9: Ativo não circulante | D9: =D10 -> 784017.14 | F9: Capital a integralizar | G9: -200000
C10: Realizável a longo prazo - outros investimentos | D10: 784017.14 | F10: Reseva de Lucros | G10: 199700.6

Sheet Embrafisa Consul.
B3: EMBRAFISA CONSUL. EMPRE. CORRE. DE SEGU. E EMPREEND. IMOB. LTDA | C3: Lucro Presumido | G3: 45627 | H3: Balanço | L3: Excel: LALUR
B4: Ativos | D4: =SUM(D5+D12) -> 1.2237116e+08 | E4: Passivos | G4: =SUM(G5+G10) -> 1.2237116e+08
B5: Ativos circulantes | D5: =SUM(D6:D11) -> 14442337 | E5: Passivos circulantes | G5: =SUM(G6:G9) -> 21461592
C6: Caixa e equivalentes | D6: 2437109.3 | F6: Obrigações trib. | G6: 2494169
C7: clientes | D7: 7001150.1 | F7: Obrigações Trab. | G7: 558759.63
C8: adiantamentos | D8: 1273637.1 | F8: Contas a pagar | G8: 17920182
C9: Estoques | D9: 3718389.1 | F9: Previsão de adiantamento de clientes | G9: 488481.84
C10: Impostos a compensar | D10: 1006.72 | E10: Patrimônio líquido | G10: =SUM(G11:G12) -> 1.0090957e+08
C11: Ações Judiciais | D11: 11044.49 | F11: Capital subscrito e integralizado | G11: 86545880
B12: Ativo não circulante | D12: =SUM(D13:D14) -> 1.0792883e+08 | F12: Reserva de lucros | G12: 14363691
C13: Investimentos | D13: 46794804
C14: Imobilizado | D14: 61134022

Sheet GSJ
B3: COMPANHIA GSJ DE PART. | C3: Lucro Presumido | G3: 45627 | L3: Excel: LALUR
B4: Ativos | D4: =SUM(D5+D9) -> 1.0937994e+08 | E4: Passivos | G4: =SUM(G5+G9) -> 1.0937994e+08 | H4: GSJ Balanço
B5: Ativos circulantes | D5: =SUM(D6:D8) -> 820384.91 | E5: Passivos circulantes | G5: =SUM(G6:G8) -> 919578.08
C6: Caixa e equivalente | D6: 7 | F6: Fiscais e Previdenciarias | G6: 6731.94
C7: Titulos e valores mobiliarios | D7: 501276.83 | F7: Diversas | G7: 360471.48
C8: Outros creditos | D8: 319101.08 | F8: Dividendos a pagar | G8: 552374.66
B9: Ativo não circulante | D9: =SUM(D10:D12) -> 1.0855956e+08 | E9: Patrimônio líquido | G9: =SUM(G10:G14) -> 1.0846036e+08
C10: Participação societárias | D10: 64315927 | F10: Capital subscrito e integralizado | G10: 79875998
C11: Outros investimentos | D11: 21372770 | F11: Capital a integralizar | G11: -2603500
C12: Imobilizado | D12: 22870861 | F12: Reserva legal | G12: 1800035.9
F13: reserva de lucros | G13: 7330593.3
F14: Lucros/Prejuizos acumulados | G14: 22057238
