Workbook

Sheet Premissas
B1: Premissas
B3: PREMISSAS GERAIS
B4: Data-base dos balanços | C4: 30.06.2026
B5: Unidade | C5: R$ milhões
B6: Participação das Partes CNP na incorporação (relação de troca) | C6: 0.138
B7: Participação-alvo final das Partes CNP | C7: 0.4
B8: IRPJ/CSLL — ganho de capital PJ | C8: 0.34
B9: Dividendos declarados pela Embracon antes da incorporação | C9: 120
B11: SEGREGAÇÃO DO CUSTO — PROPORÇÃO DO EXEMPLO DELOITTE (ILUSTRATIVO)
B12: Valor justo do PL da CNP (exemplo DTT) | C12: 866
B13: Mais-valia / AVJ contida no exemplo (MV) | C13: 300
B14: % AVJ implícito no PL da CNP | C14: =C13/C12 -> 0.34642032
B15: % contábil (sem AVJ) | C15: =1-C14 -> 0.65357968
B17: CASH OUT
B18: Preço por holding (venda à CNP Participações) | C18: 600
B20: DESTINAÇÃO DO CAIXA E APLICAÇÕES (PREMISSAS DO DRAFT — A VALIDAR)
B21: IRRF sobre dividendos ao sócio PF | C21: 0.1
B22: CDI (a.a.) | C22: 0.12
B23: % do CDI — aplicação na PJ (holding) | C23: 1
B24: % do CDI — aplicação na PF | C24: 1.05
B25: IR sobre rendimentos — PJ | C25: 0.34
B26: IR sobre rendimentos — PF | C26: 0.27
B27: Horizonte de comparação (anos) | C27: 2

Sheet 1. Situação Antes
B1: 1. Situação antes da incorporação — balanços 30.06.2026
B2: BALANÇOS DE PARTIDA (R$ MILHÕES)
B4: SAVIAN | E4: JVFJ | H4: EMBRACON | K4: CNP CONSÓRCIO
B5: ATIVOS | C5: =SUM(C6:C10) -> 119.744 | E5: ATIVOS | F5: =SUM(F6:F10) -> 119.744 | H5: ATIVOS | I5: =SUM(I6:I10) -> 26138.03 | K5: ATIVOS | L5: =SUM(L6:L10) -> 17611.435
B6: Circulante | E6: Circulante | H6: Circulante | I6: 328.578 | K6: Circulante | L6: 945.234
B7: CPC 47 (despesas/comissões diferidas) | E7: CPC 47 (despesas/comissões diferidas) | H7: CPC 47 (despesas/comissões diferidas) | I7: 1937.402 | K7: CPC 47 (despesas/comissões diferidas) | L7: 216.353
B8: Permanente | E8: Permanente | H8: Permanente | I8: 57.986 | K8: Permanente | L8: 138.693
B9: Inv. Embracon | C9: =I18/2 -> 119.744 | E9: Inv. Embracon | F9: =I18/2 -> 119.744 | H9: Inv. Embracon | K9: Inv. Embracon
B10: Compensação (grupos de consórcio) | E10: Compensação (grupos de consórcio) | H10: Compensação (grupos de consórcio) | I10: 23814.064 | K10: Compensação (grupos de consórcio) | L10: 16311.155
B12: PASSIVOS | C12: =SUM(C13:C16) -> 0 | E12: PASSIVOS | F12: =SUM(F13:F16) -> 0 | H12: PASSIVOS | I12: =SUM(I13:I16) -> 25898.882 | K12: PASSIVOS | L12: =SUM(L13:L16) -> 16771.856
B13: Circulante | E13: Circulante | H13: Circulante | I13: 420.06 | K13: Circulante | L13: 232.757
B14: CPC 47 (receitas diferidas) | E14: CPC 47 (receitas diferidas) | H14: CPC 47 (receitas diferidas) | I14: 1544.758 | K14: CPC 47 (receitas diferidas) | L14: 227.944
B15: Dividendos a pagar | E15: Dividendos a pagar | H15: Dividendos a pagar | I15: =Premissas!C9 -> 120 | K15: Dividendos a pagar
B16: Compensação (grupos de consórcio) | E16: Compensação (grupos de consórcio) | H16: Compensação (grupos de consórcio) | I16: =I10 -> 23814.064 | K16: Compensação (grupos de consórcio) | L16: =L10 -> 16311.155
B18: PATRIMÔNIO LÍQUIDO | C18: =SUM(C19:C21) -> 119.744 | E18: PATRIMÔNIO LÍQUIDO | F18: =SUM(F19:F21) -> 119.744 | H18: PATRIMÔNIO LÍQUIDO | I18: =SUM(I19:I21) -> 239.488 | K18: PATRIMÔNIO LÍQUIDO | L18: =SUM(L19:L21) -> 838.735
B19: Capital | C19: =C9 -> 119.744 | E19: Capital | F19: =F9 -> 119.744 | H19: Capital | I19: 85 | K19: Capital | L19: 519
B20: Reservas | E20: Reservas | H20: Reservas | I20: 274.488 | K20: Reservas | L20: 319.735
B21: (−) Dividendos declarados | E21: (−) Dividendos declarados | H21: (−) Dividendos declarados | I21: =-Premissas!C9 -> -120 | K21: (−) Dividendos declarados
B23: PASSIVOS + PL | C23: =C12+C18 -> 119.744 | E23: PASSIVOS + PL | F23: =F12+F18 -> 119.744 | H23: PASSIVOS + PL | I23: =I12+I18 -> 26138.37 | K23: PASSIVOS + PL | L23: =L12+L18 -> 17610.591
B24: Check (Ativos − Passivos − PL) | C24: =C5-C23 -> 0 | E24: Check (Ativos − Passivos − PL) | F24: =F5-F23 -> 0 | H24: Check (Ativos − Passivos − PL) | I24: =I5-I23 -> -0.34 | K24: Check (Ativos − Passivos − PL) | L24: =L5-L23 -> 0.844
B27: PROPORCIONALIDADE DOS PLs "NOMINAIS"
B28: Entidade | C28: PL 30.06.26 | D28: % do PL combinado
B29: Embracon | C29: =I18 -> 239.488 | D29: =C29/C31 -> 0.22211361
B30: CNP Consórcio | C30: =L18 -> 838.735 | D30: =C30/C31 -> 0.77788639
B31: PL combinado | C31: =C29+C30 -> 1078.223 | D31: =C31/C31 -> 1

Sheet 2. Incorporação CPC 15
B1: 2. Incorporação da CNP pela Embracon (CPC 15 — atos a valor contábil)
B3: RELAÇÃO DE TROCA E PARTICIPAÇÕES | H3: EMBRACON COMBINADA — BALANÇO APÓS (VALOR CONTÁBIL)
B4: Acionista | C4: Antes | D4: Após incorporação | H4: Linha | I4: Embracon | J4: CNP | K4: Combinada
B5: Cia. Savian | C5: 0.5 | D5: =C5*(1-Premissas!C6) -> 0.431 | H5: Ativo circulante | I5: ='1. Situação Antes'!I6 -> 328.578 | J5: ='1. Situação Antes'!L6 -> 945.234 | K5: =I5+J5 -> 1273.812
B6: Cia. JVFJ | C6: 0.5 | D6: =C6*(1-Premissas!C6) -> 0.431 | H6: Ativo CPC 47 | I6: ='1. Situação Antes'!I7 -> 1937.402 | J6: ='1. Situação Antes'!L7 -> 216.353 | K6: =I6+J6 -> 2153.755
B7: Partes CNP (ações novas) | C7: 0 | D7: =Premissas!C6 -> 0.138 | H7: Permanente | I7: ='1. Situação Antes'!I8 -> 57.986 | J7: ='1. Situação Antes'!L8 -> 138.693 | K7: =I7+J7 -> 196.679
B8: Total | C8: =SUM(C5:C7) -> 1 | D8: =SUM(D5:D7) -> 1 | H8: Compensação (ativo) | I8: ='1. Situação Antes'!I10 -> 23814.064 | J8: ='1. Situação Antes'!L10 -> 16311.155 | K8: =I8+J8 -> 40125.219
H9: Passivo circulante | I9: ='1. Situação Antes'!I13 -> 420.06 | J9: ='1. Situação Antes'!L13 -> 232.757 | K9: =I9+J9 -> 652.817
B10: REFLEXO NAS HOLDINGS (MEP) — CUSTO DO INVESTIMENTO | H10: Passivo CPC 47 | I10: ='1. Situação Antes'!I14 -> 1544.758 | J10: ='1. Situação Antes'!L14 -> 227.944 | K10: =I10+J10 -> 1772.702
B11: Item | C11: Por holding | D11: Total (2 holdings) | H11: Dividendos a pagar | I11: ='1. Situação Antes'!I15 -> 120 | J11: ='1. Situação Antes'!L15 -> 0 | K11: =I11+J11 -> 120
B12: Investimento anterior (custo original — "magrinho") | C12: ='1. Situação Antes'!C9 -> 119.744 | D12: =C12*2 -> 239.488 | H12: Compensação (passivo) | I12: ='1. Situação Antes'!I16 -> 23814.064 | J12: ='1. Situação Antes'!L16 -> 16311.155 | K12: =I12+J12 -> 40125.219
B13: (+) Incorporação base (reflexo do PL contábil da CNP ÷ 2) | C13: ='1. Situação Antes'!L18/2 -> 419.3675 | D13: =C13*2 -> 838.735 | H13: Capital social | I13: ='1. Situação Antes'!I19 -> 85 | J13: ='1. Situação Antes'!L19 -> 519 | K13: =I13+J13 -> 604
B14: (−) Diluição (13,8% sobre investimento + base) | C14: =-(C12+C13)*Premissas!C6 -> -74.397387 | D14: =C14*2 -> -148.79477 | H14: Reservas | I14: ='1. Situação Antes'!I20 -> 274.488 | J14: ='1. Situação Antes'!L20 -> 319.735 | K14: =I14+J14 -> 594.223
B15: (=) Parcela incorporada (líquida) | C15: =C13+C14 -> 344.97011 | D15: =C15*2 -> 689.94023 | H15: (−) Dividendos | I15: ='1. Situação Antes'!I21 -> -120 | J15: ='1. Situação Antes'!L21 -> 0 | K15: =I15+J15 -> -120
B16: (=) Custo final do investimento ("gordinho") | C16: =C12+C15 -> 464.71411 | D16: =C16*2 -> 929.42823 | H16: PL combinado | I16: ='1. Situação Antes'!I18 -> 239.488 | J16: ='1. Situação Antes'!L18 -> 838.735 | K16: =I16+J16 -> 1078.223
B17: Check: 43,1% × PL combinado | C17: =D5*K16-C16 -> 0 | H17: Check (A − P − PL) | I17: =SUM(I5:I8)-SUM(I9:I12)-I16 -> -0.34 | J17: =SUM(J5:J8)-SUM(J9:J12)-J16 -> 0.844 | K17: =SUM(K5:K8)-SUM(K9:K12)-K16 -> 0.504
B19: LANÇAMENTOS CONTÁBEIS NAS HOLDINGS (CADA UMA)
B20: Lançamento | C20: Débito | D20: Crédito
B21: 1. Reflexo da incorporação — Inv. Embracon | C21: =C13 -> 419.3675
B22: 2. Perda de diluição — Inv. Embracon | D22: =-C14 -> 74.397387
B23: Efeito líquido no investimento | C23: =C21-D22 -> 344.97011
B25: SEGREGAÇÃO DE RISCO DO CUSTO
B26: Camada | C26: PL combinado | D26: Antes) | E26: Depois | F26: Δ (2 holdings)
B27: 1. Investimento antigo (PL Embracon) — perda de diluição | C27: ='1. Situação Antes'!I18 -> 239.488 | D27: =C27 -> 239.488 | E27: =C27*(1-Premissas!C6) -> 206.43866 | F27: =E27-D27 -> -33.049344
B28: 2. Reflexo do PL contábil da CNP (menor risco) | C28: ='1. Situação Antes'!L18*Premissas!C15 -> 548.18015 | D28: 0 | E28: =C28*(1-Premissas!C6) -> 472.53129 | F28: =E28-D28 -> 472.53129
B29: 3. Reflexo da parcela AVJ implícita (maior risco) | C29: ='1. Situação Antes'!L18*Premissas!C14 -> 290.55485 | D29: 0 | E29: =C29*(1-Premissas!C6) -> 250.45828 | F29: =E29-D29 -> 250.45828
B30: Novo Embracon (soma) | C30: =SUM(C27:C29) -> 1078.223 | D30: =SUM(D27:D29) -> 239.488 | E30: =SUM(E27:E29) -> 929.42823 | F30: =SUM(F27:F29) -> 689.94023

Sheet 3. Cash Out
B1: 3. Cash out — venda de 26,2% à CNP (etapa 2, simultânea)
B3: PARÂMETROS DA ETAPA
B4: Pontos percentuais vendidos — total (40% − 13,8%) | C4: =Premissas!C7-Premissas!C6 -> 0.262
B5: Pontos percentuais vendidos — por holding | C5: =C4/2 -> 0.131
B6: Participação de cada holding após a incorporação | C6: ='2. Incorporação CPC 15'!D5 -> 0.431
B7: Fração alienada do investimento (13,1 ÷ 43,1) | C7: =C5/C6 -> 0.30394432
B8: Preço por holding | C8: =Premissas!C18 -> 600
B10: PARTICIPAÇÕES: APÓS INCORPORAÇÃO / VENDA / FINAL
B11: Acionista | C11: Após incorp. | D11: Venda | F11: Final
B12: Cia. Savian | C12: ='2. Incorporação CPC 15'!D5 -> 0.431 | D12: =-$C$5 -> -0.131 | F12: =C12+D12 -> 0.3
B13: Cia. JVFJ | C13: ='2. Incorporação CPC 15'!D6 -> 0.431 | D13: =-$C$5 -> -0.131 | F13: =C13+D13 -> 0.3
B14: Partes CNP | C14: ='2. Incorporação CPC 15'!D7 -> 0.138 | D14: =$C$4 -> 0.262 | F14: =C14+D14 -> 0.4
B15: Total | C15: =SUM(C12:C14) -> 1 | D15: =SUM(D12:D14) -> 0 | F15: =SUM(F12:F14) -> 1
B17: GANHO DE CAPITAL — DUAS HIPÓTESES DE CUSTO
C18: Por holding | F18: Total (2 holdings)
B19: Item | C19: Hip. A — custo original | D19: Hip. B — custo incrementado | F19: Hip. A | G19: Hip. B
B20: Preço da alienação | C20: =$C$8 -> 600 | D20: =$C$8 -> 600 | F20: =C20*2 -> 1200 | G20: =D20*2 -> 1200
B21: Custo total do investimento | C21: ='2. Incorporação CPC 15'!C12 -> 119.744 | D21: ='2. Incorporação CPC 15'!C16 -> 464.71411 | F21: =C21*2 -> 239.488 | G21: =D21*2 -> 929.42823
B22: Custo alocado à parcela alienada (× fração 30,39%) | C22: =C21*$C$7 -> 36.395508 | D22: =D21*$C$7 -> 141.24721 | F22: =C22*2 -> 72.791016 | G22: =D22*2 -> 282.49443
B23: Ganho de capital | C23: =C20-C22 -> 563.60449 | D23: =D20-D22 -> 458.75279 | F23: =C23*2 -> 1127.209 | G23: =D23*2 -> 917.50557
B24: IRPJ/CSLL (34%) | C24: =C23*Premissas!C8 -> 191.62553 | D24: =D23*Premissas!C8 -> 155.97595 | F24: =C24*2 -> 383.25105 | G24: =D24*2 -> 311.9519
B25: Líquido do imposto (preço − IR) | C25: =C20-C24 -> 408.37447 | D25: =D20-D24 -> 444.02405 | F25: =C25*2 -> 816.74895 | G25: =D25*2 -> 888.0481
B26: Alíquota efetiva sobre o preço | C26: =C24/C20 -> 0.31937588 | D26: =D24/D20 -> 0.25995991 | F26: =F24/F20 -> 0.31937588 | G26: =G24/G20 -> 0.25995991
B27: Custo remanescente (para a alienação futura) | C27: =C21-C22 -> 83.348492 | D27: =D21-D22 -> 323.4669 | F27: =C27*2 -> 166.69698 | G27: =D27*2 -> 646.9338
B28: Economia de IR da Hipótese B nesta etapa | C28: =C24-D24 -> 35.64958 | F28: =F24-G24 -> 71.299159

Sheet 4. Caixa PJ x PF
B1: 4. Destinação do caixa do cash out — manter na PJ x distribuir à PF
B3: BASE
B4: Líquido do cash out na holding (após IR de 34%) | C4: ='3. Cash Out'!C25 -> 408.37447
B5: IRRF na distribuição de dividendos à PF (10%) | C5: =C4*Premissas!C21 -> 40.837447
B6: Líquido disponível na PF | C6: =C4-C5 -> 367.53703
B8: APLICAÇÃO FINANCEIRA (ILUSTRAÇÃO DE 2 ANOS)
B9: Item | C9: Manter na PJ | D9: Distribuir à PF
B10: Saldo inicial | C10: =C4 -> 408.37447 | D10: =C6 -> 367.53703
B11: Ano 1 — rendimento bruto | C11: =C10*Premissas!C22*Premissas!C23 -> 49.004937 | D11: =D10*Premissas!C22*Premissas!C24 -> 46.309665
B12: Ano 1 — IR sobre o rendimento | C12: =-C11*Premissas!C25 -> -16.661678 | D12: =-D11*Premissas!C26 -> -12.50361
B13: Saldo ao fim do ano 1 | C13: =SUM(C10:C12) -> 440.71773 | D13: =SUM(D10:D12) -> 401.34308
B14: Ano 2 — rendimento bruto | C14: =C13*Premissas!C22*Premissas!C23 -> 52.886128 | D14: =D13*Premissas!C22*Premissas!C24 -> 50.569228
B15: Ano 2 — IR sobre o rendimento | C15: =-C14*Premissas!C25 -> -17.981283 | D15: =-D14*Premissas!C26 -> -13.653692
B16: Saldo ao fim do ano 2 | C16: =SUM(C13:C15) -> 475.62258 | D16: =SUM(D13:D15) -> 438.25862
B17: Vantagem de manter na PJ (fim do ano 2) | C17: =C16-D16 -> 37.363958

Sheet 5. Alienação Futura
B1: 5. Alienação futura (cenário hipotético)
B3: BASE (POR HOLDING)
B4: Participação remanescente | C4: ='3. Cash Out'!F12 -> 0.3
B5: Custo remanescente — Hip. A (custo original) | C5: ='3. Cash Out'!C27 -> 83.348492
B6: Custo remanescente — Hip. B (custo incrementado) | C6: ='3. Cash Out'!D27 -> 323.4669
B7: Diferença de custo (B − A) | C7: =C6-C5 -> 240.11841
B9: SENSIBILIDADE — PREÇO DA VENDA FUTURA (POR HOLDING, R$ MILHÕES)
B10: Preço da venda futura (editável) | C10: 300 | D10: 600 | E10: 900 | F10: 1200 | G10: 1500
B11: Ganho de capital — Hip. A | C11: =C10-$C$5 -> 216.65151 | D11: =D10-$C$5 -> 516.65151 | E11: =E10-$C$5 -> 816.65151 | F11: =F10-$C$5 -> 1116.6515 | G11: =G10-$C$5 -> 1416.6515
B12: IRPJ/CSLL 34% — Hip. A | C12: =MAX(0,C11)*Premissas!C8 -> 73.661513 | D12: =MAX(0,D11)*Premissas!C8 -> 175.66151 | E12: =MAX(0,E11)*Premissas!C8 -> 277.66151 | F12: =MAX(0,F11)*Premissas!C8 -> 379.66151 | G12: =MAX(0,G11)*Premissas!C8 -> 481.66151
B13: Ganho de capital — Hip. B | C13: =C10-$C$6 -> -23.4669 | D13: =D10-$C$6 -> 276.5331 | E13: =E10-$C$6 -> 576.5331 | F13: =F10-$C$6 -> 876.5331 | G13: =G10-$C$6 -> 1176.5331
B14: IRPJ/CSLL 34% — Hip. B | C14: =MAX(0,C13)*Premissas!C8 -> 0 | D14: =MAX(0,D13)*Premissas!C8 -> 94.021254 | E14: =MAX(0,E13)*Premissas!C8 -> 196.02125 | F14: =MAX(0,F13)*Premissas!C8 -> 298.02125 | G14: =MAX(0,G13)*Premissas!C8 -> 400.02125
B15: Economia de IR da Hip. B (A − B) | C15: =C12-C14 -> 73.661513 | D15: =D12-D14 -> 81.640259 | E15: =E12-E14 -> 81.640259 | F15: =F12-F14 -> 81.640259 | G15: =G12-G14 -> 81.640259
B16: Idem, total 2 holdings | C16: =C15*2 -> 147.32303 | D16: =D15*2 -> 163.28052 | E16: =E15*2 -> 163.28052 | F16: =F15*2 -> 163.28052 | G16: =G15*2 -> 163.28052

Sheet 6. Segregação de Risco
B1: 6. Segregação de risco do custo do investimento — CPC 15 × CPC 19 e venda futura dos 60% (reprodução dos quadros da MLA)
B3: PREMISSAS DESTA ABA (VINCULADAS ÀS DEMAIS ABAS; AZUL = INPUT DO EXERCÍCIO DTT/MLA)
B4: PL da Embracon 30.06.26 (com dividendos) | C4: ='1. Situação Antes'!I18 -> 239.488 | H4: aba 1
B5: PL da CNP 30.06.26 | C5: ='1. Situação Antes'!L18 -> 838.735 | H5: aba 1
B6: PL combinado (Embracon + CNP) | C6: =C4+C5 -> 1078.223
B7: Participação das Partes CNP na incorporação | C7: =Premissas!C6 -> 0.138 | H7: Premissas
B8: Participação final das Partes CNP (pós cash out) | C8: =Premissas!C7 -> 0.4 | H8: Premissas
B9: Participação final das holdings (posição remanescente) | C9: =1-C8 -> 0.6
B10: IRPJ/CSLL sobre ganho de capital (PJ) | C10: =Premissas!C8 -> 0.34 | H10: Premissas
B11: % contábil do PL da CNP (proporção DTT: 566 ÷ 866) | C11: =Premissas!C15 -> 0.65357968 | H11: Premissas
B12: % AVJ implícito no PL da CNP (proporção DTT: 300 ÷ 866) | C12: =Premissas!C14 -> 0.34642032 | H12: Premissas
B13: VJ da JO — 100% (exercício DTT) | C13: 5888 | H13: draft O90 — input
B14: VJ da CNP (exercício DTT) | C14: =Premissas!C12 -> 866 | H14: Premissas (866)
B15: VJ da Embracon (residual = VJ JO − VJ CNP) | C15: =C13-C14 -> 5022 | H15: draft O92
B16: Custo antigo baixado na secundária — critério do draft (13,1% × custo, 2 holdings) | C16: =C4*(C8-C7)/2 -> 31.372928 | H16: draft F100: 239,5 × 13,1% = 31,4 (a aba 3 usa rateio 13,1/43,1)
B17: Custo do investimento das PFs nas holdings (draft: 18) | C17: 18 | H17: draft Z78 — input
B18: Alíquota simplificada de IRPF sobre o ganho (venda pela PF) | C18: 0.225 | H18: draft — input
B19: Preço de venda futura dos 60% — cenário (i) inferior ao EV | C19: 1000 | H19: input
B20: Preço de venda futura dos 60% — cenário (ii) = VJ da posição (60% × VJ JO) | C20: =C13*C9 -> 3532.8 | H20: 3.532,8
B21: Preço de venda futura dos 60% — cenário (iii) superior ao EV | C21: 5000 | H21: input
B23: A. CPC 15 — SEGREGAÇÃO DE RISCO DO CUSTO DO INVESTIMENTO (POSIÇÃO FINAL DE 60%) — QUADRO 'MLA - SEGREGAÇÃO RISCO CUSTO DO INVESTIMENTO'
B24: Camada do custo | C24: TOTAL (PL combinado) | D24: ANTES | E24: DEPOIS (60%) | F24: Δ | H24: LEITURA
B25: 1. Inv Embracon — custo antigo | C25: =C4 -> 239.488 | D25: =C4 -> 239.488 | E25: =D25-C16 -> 208.11507 | F25: =E25-D25 -> -31.372928 | H25: Custo histórico das holdings menos o custo baixado na secundária (31,4). No draft, rotulado 'PERDA DILUIÇÃO'. Camada incontroversa.
B26: 2. Inv CNP (PL contábil) — reflexo PL | C26: =C5*C11 -> 548.18015 | D26: 0 | E26: =E28-E25-E27 -> 264.48582 | F26: =E26-D26 -> 264.48582 | H26: Reflexo do PL contábil da CNP: residual para fechar 60% × PL combinado (draft T85 = 646,9 − 208,1 − 174,3). Neutralidade defensável (MEP / variação de participação) — risco menor.
B27: 3. Inv CNP (AVJ) — reflexo AVJ | C27: =C5*C12 -> 290.55485 | D27: 0 | E27: =C27*C9 -> 174.33291 | F27: =E27-D27 -> 174.33291 | H27: Reflexo da parcela AVJ implícita no PL da CNP (34,6%), proporcional à posição (60% × 290,6). Maior risco de requalificação (AVJ reflexo).
B28: NOVO EMBRACON — custo do investimento (Hipótese B, 'gordinho') | C28: =SUM(C25:C27) -> 1078.223 | D28: =SUM(D25:D27) -> 239.488 | E28: =C28*C9 -> 646.9338 | F28: =E28-D28 -> 407.4458 | H28: DEPOIS = 60% × PL combinado (1.078,2 × 60% = 646,9): é o custo incrementado da posição remanescente — o mesmo 'custo remanescente B' da aba 3, na visão do draft.
B29: Check: soma das camadas − 60% × PL combinado | C29: =E25+E26+E27-E28 -> 0
B30: Memo (draft S85): Inv Embracon depois + AVJ depois | C30: =E25+E27 -> 382.44798 | H30: 382,4 — as duas camadas 'diretas'; o reflexo PL é o que sobra (T85 = 264,5).
B31: Memo: alíquota × camadas de reflexo (IR potencial se negadas): reflexo PL · reflexo AVJ | C31: =E26*C10 -> 89.925178 | D31: =E27*C10 -> 59.273189 | H31: 89,9 e 59,3 — são exatamente os 'degraus' dos riscos 1 e 2 do bloco D.
B33: B. CPC 19 — SEGREGAÇÃO DO AVJ REFLEXO NAS HOLDINGS (JOINT OPERATION) — QUADRO 'MLA - SEGREGAÇÃO AVJ REFLEXO HOLDINGS DA EMBRACON'
B34: Item | C34: 100% JO | D34: 60% (holdings) | H34: LEITURA
B35: Inv JO (contábil) = PL Embracon + parcela contábil do PL da CNP | C35: =C4+C5*C11 -> 787.66815 | D35: =C35*C9 -> 472.60089 | H35: Base contábil da JO (239,5 + 548,2 = 787,7); 60% = 472,6. É o custo fiscal 'magro' na JO — reflexo patrimonial.
B36: AVJ JO = VJ da JO − base contábil | C36: =C13-C35 -> 5100.3318 | D36: =C13*C9-D35 -> 3060.1991 | H36: Reavaliação a valor justo de TODO o negócio (CNP e Embracon): 5.100,3; 60% = 3.060,2. Diferido em subconta; passivo fiscal diferido.
B37: NOVO EMBRACON a valor justo (Inv JO) | C37: =C35+C36 -> 5888 | D37: =D35+D36 -> 3532.8 | H37: 5.888 (100%) e 3.532,8 (60%) — valor pelo qual as holdings reconhecem a participação no CPC 19.
B38: 'Carimbo': tributação diferida do AVJ (34%) | C38: =C36*C10 -> 1734.1128 | D38: =D36*C10 -> 1040.4677 | H38: 1.040,5 nos 60% — devido na realização (alienação/baixa), qualquer que seja o preço; é o piso da carga no CPC 19.
B40: C. VENDA FUTURA DOS 60% — PJ × PF × CPC 15 / CPC 19 — QUADRO 'VENDA PJ / VENDA PF'
B41: Preço da venda (60%) | C41: CPC 15 — venda pela PJ | D41: CPC 19 — venda pela PJ | E41: CPC 15 — venda pela PF | F41: CPC 19 — venda pela PF | H41: LEITURA
B42: =C19 -> 1000 | C42: =(B42-$E$28)*$C$10 -> 120.04251 | D42: =MAX($D$38,(B42-$D$35)*$C$10) -> 1040.4677 | E42: =(B42-$C$17)*$C$18 -> 220.95 | F42: =$D$38+MAX(0,B42-$C$20)*$C$18 -> 1040.4677 | H42: Preço inferior ao EV: no CPC 19 o carimbo (1.040) prevalece sobre 34% × ganho; no CPC 15 tributa-se só o ganho sobre o custo 'gordinho' (646,9).
B43: =C20 -> 3532.8 | C43: =(B43-$E$28)*$C$10 -> 981.19451 | D43: =MAX($D$38,(B43-$D$35)*$C$10) -> 1040.4677 | E43: =(B43-$C$17)*$C$18 -> 790.83 | F43: =$D$38+MAX(0,B43-$C$20)*$C$18 -> 1040.4677 | H43: Preço = VJ da posição: CPC 15 981 × CPC 19 1.040 — a diferença (59,3) é 34% × camada AVJ (174,3): no CPC 19 o AVJ da própria Embracon é tributado; no CPC 15 não é reavaliado.
B44: =C21 -> 5000 | C44: =(B44-$E$28)*$C$10 -> 1480.0425 | D44: =MAX($D$38,(B44-$D$35)*$C$10) -> 1539.3157 | E44: =(B44-$C$17)*$C$18 -> 1120.95 | F44: =$D$38+MAX(0,B44-$C$20)*$C$18 -> 1370.5877 | H44: Preço superior ao EV: CPC 19 = 34% × (preço − 472,6) — tributa integralmente o excedente sobre a base contábil; PF paga o carimbo na holding + 22,5% sobre o excedente acima do VJ.
...

Sheet Conclusão
B1: Conclusão — síntese das duas hipóteses de custo
B3: SÍNTESE (TOTAL DAS 2 HOLDINGS, R$ MILHÕES)
B4: Item | C4: Hip. A — custo original | D4: Hip. B — custo incrementado | E4: Δ (economia B)
B5: Custo total do investimento após a incorporação | C5: ='2. Incorporação CPC 15'!C12*2 -> 239.488 | D5: ='2. Incorporação CPC 15'!C16*2 -> 929.42823 | E5: =D5-C5 -> 689.94023
B6: IR no cash out (etapa 3) | C6: ='3. Cash Out'!F24 -> 383.25105 | D6: ='3. Cash Out'!G24 -> 311.9519 | E6: =C6-D6 -> 71.299159
B7: Custo remanescente para o passo F | C7: ='3. Cash Out'!C27*2 -> 166.69698 | D7: ='3. Cash Out'!D27*2 -> 646.9338 | E7: =D7-C7 -> 480.23682
B8: Economia futura máxima da Hip. B (34% × Δ custo remanescente) | E8: =E7*Premissas!C8 -> 163.28052
B9: BENEFÍCIO TOTAL DA TESE DO CUSTO "GORDINHO" | E9: =E6+E8 -> 234.57968
B10: Check: 34% × parcela incorporada total (689,94) | E10: =E9-'2. Incorporação CPC 15'!D15*Premissas!C8 -> 0
