Workbook

Sheet Premissas
E1: Projeto Another House — Exercício da Incorporação sob CPC 15
E2: Hipótese A: custo original ("magrinho") · Hipótese B: custo incrementado ("gordinho")
B4: Base: draft MLA, aba "base 30 06 26com dividendos" · valores em R$ milhões · células AMARELAS = premissas editáveis; o restante é fórmula.
B6: PREMISSAS GERAIS
B7: Data-base dos balanços | C7: 30.06.2026
B8: Participação das Partes CNP na incorporação (relação de troca) | C8: 0.138 | D8: Draft E71
B9: Participação final das Partes CNP (pós cash out) | C9: 0.4 | D9: Draft E87
B10: IRPJ/CSLL sobre ganho de capital | C10: 0.34 | D10: Draft I96
B11: Dividendos declarados pela Embracon antes da incorporação | C11: 120 | D11: Draft L23/L31 — reduz o PL da Embracon a 239,5
B12: Preço do cash out — por holding | C12: 600 | D12: Draft G97 (total 1.200 nas duas holdings)
B14: SEGREGAÇÃO DO CUSTO — PROPORÇÃO DO EXEMPLO DELOITTE
B15: Valor justo do PL da CNP (exemplo DTT) | C15: 866 | D15: Draft N86
B16: Mais-valia contida no exemplo (MV) | C16: 300 | D16: Draft O86
B17: % AVJ implícito no PL da CNP (MV ÷ VJ) | C17: =C16/C15 -> 0.34642032 | D17: Aplicado ao PL contábil da CNP para segregar a camada de maior risco
B18: % contábil (sem AVJ) | C18: =1-C17 -> 0.65357968

Sheet Contabilização
B1: Contabilização — do balanço-base à alienação futura
B3: 0. BALANÇOS-BASE 30.06.2026 (R$ MILHÕES)
C4: SAVIAN | D4: JVFJ | E4: EMBRACON | F4: CNP
B5: Ativos totais | C5: =C11 -> 119.744 | D5: =D11 -> 119.744 | E5: 26138.03 | F5: 17611.435
B6: Passivos totais | C6: 0 | D6: 0 | E6: 25898.882 | F6: 16771.856
B7: Patrimônio líquido | C7: =E7/2 -> 119.744 | D7: =E7/2 -> 119.744 | E7: =SUM(E8:E10) -> 239.488 | F7: =SUM(F8:F10) -> 838.735
B8: Capital | E8: 85 | F8: 519
B9: Reservas | E9: 274.488 | F9: 319.735
B10: (−) Dividendos declarados | E10: =-Premissas!$C$11 -> -120
B11: Investimento na Embracon (= 50% do PL) | C11: =E7/2 -> 119.744 | D11: =E7/2 -> 119.744
B12: PL combinado (Embracon + CNP) | C12: =E7+F7 -> 1078.223
B13: Savian e JVFJ: ativo único = investimento na Embracon. CNP: PL = Capital 519 + Reservas 319,7 (draft).
B15: 1. PRÉ-INCORPORAÇÃO — PARTICIPAÇÕES E CUSTO
C16: SAVIAN | D16: JVFJ | E16: CNP | F16: TOTAL
B17: Participação na Embracon | C17: 0.5 | D17: 0.5 | E17: 0 | F17: =SUM(C17:E17) -> 1
B18: Custo do investimento | C18: =C11 -> 119.744 | D18: =D11 -> 119.744 | F18: =C18+D18 -> 239.488
B20: 2. INCORPORAÇÃO DA CNP — RELAÇÃO DE TROCA 13,8%
C21: SAVIAN | D21: JVFJ | E21: CNP | F21: TOTAL
B22: Participação após a incorporação | C22: =C17*(1-Premissas!$C$8) -> 0.431 | D22: =D17*(1-Premissas!$C$8) -> 0.431 | E22: =Premissas!$C$8 -> 0.138 | F22: =SUM(C22:E22) -> 1
B24: Reflexo nas holdings | C24: POR HOLDING | D24: TOTAL (2 HOLDINGS)
B25: Investimento anterior | C25: =C11 -> 119.744 | D25: =C25*2 -> 239.488
B26: (+) Incorporação base (PL da CNP ÷ 2) | C26: =F7/2 -> 419.3675 | D26: =C26*2 -> 838.735
B27: (−) Diluição de 13,8% sobre (investimento + base) | C27: =-(C25+C26)*Premissas!$C$8 -> -74.397387 | D27: =C27*2 -> -148.79477
B28: (=) Parcela incorporada | C28: =C26+C27 -> 344.97011 | D28: =C28*2 -> 689.94023
B29: (=) Custo incrementado — Hipótese B ("gordinho") | C29: =C25+C28 -> 464.71411 | D29: =C29*2 -> 929.42823
B30: Check: 43,1% × PL combinado − custo incrementado | C30: =C22*C12-C29 -> 0
B32: Segregação do custo (camadas de risco) | C32: PL COMBINADO | D32: × 86,2% | E32: Δ (2 HOLDINGS)
B33: 1. Investimento antigo (PL Embracon) — perda de diluição | C33: =E7 -> 239.488 | D33: =C33*(1-Premissas!$C$8) -> 206.43866 | E33: =D33-C33 -> -33.049344
B34: 2. Reflexo do PL contábil da CNP (menor risco) | C34: =F7*Premissas!$C$18 -> 548.18015 | D34: =C34*(1-Premissas!$C$8) -> 472.53129 | E34: =D34 -> 472.53129
B35: 3. Reflexo da parcela AVJ implícita (maior risco) | C35: =F7*Premissas!$C$17 -> 290.55485 | D35: =C35*(1-Premissas!$C$8) -> 250.45828 | E35: =D35 -> 250.45828
B36: Total | C36: =SUM(C33:C35) -> 1078.223 | D36: =SUM(D33:D35) -> 929.42823 | E36: =SUM(E33:E35) -> 689.94023
B38: CONCLUSÃO DA INCORPORAÇÃO
B39: Custo original — Hipótese A (por holding) | C39: =C11 -> 119.744
B40: Custo incrementado — Hipótese B (por holding) | C40: =C29 -> 464.71411
B41: Parcela incorporada — total (2 holdings) | C41: =D28 -> 689.94023
B43: 3. SITUAÇÃO APÓS A INCORPORAÇÃO — O ACERVO VERTIDO (CINDIDO) E OS BALANÇOS
B44: 3.1 Acervo líquido da CNP vertido à Embracon (linha a linha) | C44: VALOR
B45: Ativos — Circulante + realizável LP | C45: 945.234
B46: Ativos — CPC 47 (despesas/comissões diferidas) | C46: 216.353
B47: Ativos — Permanente | C47: 138.693
...

Sheet Conclusão
B1: Conclusão — efeitos das duas hipóteses de custo
B3: SÍNTESE (TOTAL DAS 2 HOLDINGS — R$ MILHÕES)
C4: HIP. A — CUSTO ORIGINAL | D4: HIP. B — CUSTO INCREMENTADO | E4: Δ (ECONOMIA B)
B5: Custo do investimento após a incorporação | C5: =Contabilização!C11*2 -> 239.488 | D5: =Contabilização!C29*2 -> 929.42823 | E5: =D5-C5 -> 689.94023
B6: IRPJ/CSLL no cash out | C6: =Contabilização!C101*2 -> 383.25105 | D6: =Contabilização!D101*2 -> 311.9519 | E6: =C6-D6 -> 71.299159
B7: Custo remanescente para a alienação futura | C7: =Contabilização!C103*2 -> 166.69698 | D7: =Contabilização!D103*2 -> 646.9338 | E7: =D7-C7 -> 480.23682
B8: IRPJ/CSLL na alienação futura (preço editável da aba anterior) | C8: =Contabilização!C116*2 -> 351.32303 | D8: =Contabilização!D116*2 -> 188.04251 | E8: =C8-D8 -> 163.28052
B9: IRPJ/CSLL total (cash out + alienação futura) | C9: =C6+C8 -> 734.57408 | D9: =D6+D8 -> 499.9944 | E9: =C9-D9 -> 234.57968
B10: Benefício máximo da tese do custo "gordinho" (34% × parcela incorporada) | E10: =Contabilização!D28*Premissas!$C$10 -> 234.57968
B11: Check: economia no cash out + economia máxima na alienação − benefício máximo | E11: =E6+Contabilização!C120-E10 -> 0
B13: LEITURA
B14: Onde nasce a diferença | C14: Parcela incorporada de 345,0 por holding (690,0 no total) = reflexo do PL contábil da CNP (419,4) − diluição de 13,8% (74,4). Compõe custo na Hipótese B; não compõe na Hipótese A.
B15: Risco por camada | C15: Perda de diluição (33,0): menor controvérsia · reflexo do PL contábil da CNP (472,5): neutralidade defensável (MEP / variação de participação) · reflexo da parcela AVJ implícita (250,5): maior risco de requalificação.
B16: Enquadramento | C16: A definição CPC 15 x CPC 19 cabe ao auditor. Sob CPC 19, o AVJ fica "carimbado" a 34% em subconta e a Hipótese B deixa de existir.
